Workbook
Name BES입장현황: [1]전시일자별관람객!$L$3:$L$1549
Name t: OFFSET(b_line!$B$4,0,0,1,b_line!$A$1)
Name 김정기: d_gra!$C$5:$C$130
Name 김정기최근주: OFFSET(#REF!,0,0,#REF!,1)
Name 당일누적_김정기: OFFSET(#REF!,0,0,#REF!,1)
Name 당일누적_드리머: OFFSET(#REF!,0,0,#REF!,1)
Name 당일누적_마르지엘라: OFFSET(#REF!,0,0,#REF!,1)
Name 당일누적_바스키아: OFFSET(#REF!,0,0,#REF!,1)
Name 당일누적_알렉스: OFFSET(#REF!,0,0,#REF!,1)
Name 당일누적_오스틴리: OFFSET(#REF!,0,0,#REF!,1)
Name 당일누적_윤협: OFFSET(#REF!,0,0,#REF!,1)
Name 당일누적_제이알: OFFSET(#REF!,0,0,#REF!,1)
Name 당일누적_페어리: OFFSET(#REF!,0,0,#REF!,1)
Name 드리머: d_gra!$D$5:$D$130
Name 드리머최근주: OFFSET(#REF!,0,0,#REF!,1)
Name 링크테스트: #REF!
Name 마르지엘라: d_gra!$G$5:$G$130
Name 마르지엘라최근주: OFFSET(#REF!,0,0,#REF!,1)
Name 바스키아: d_gra!$B$5:$B$130
Name 바스키아최근주: OFFSET(#REF!,0,0,#REF!,1)
Name 범위_김정기: OFFSET(b_line!$C$5,0,0,1,b_line!$B$2)
Name 범위_드리머: OFFSET(b_line!$C$6,0,0,1,b_line!$B$2)
Name 범위_마르지엘라: OFFSET(b_line!$C$9,0,0,1,b_line!$B$2)
Name 범위_바스키아: OFFSET(b_line!$C$4,0,0,1,b_line!$B$2)
Name 범위_알렉스: OFFSET(b_line!$C$7,0,0,1,b_line!$B$2)
Name 범위_오스틴리: OFFSET(b_line!$C$11,0,0,1,b_line!$B$2)
Name 범위_윤협: OFFSET(b_line!$C$12,0,0,1,b_line!$B$2)
Name 범위_제이알: OFFSET(b_line!$C$10,0,0,1,b_line!$B$2)
Name 범위_페어리: OFFSET(b_line!$C$8,0,0,1,b_line!$B$2)
Name 알렉스: d_gra!$E$5:$E$130
Name 알렉스최근주: OFFSET(#REF!,0,0,#REF!,1)
Name 오스틴_리: d_gra!$I$5:$I$130
Name 오스틴최근주: OFFSET(#REF!,0,0,#REF!,1)
Name 윤협: d_gra!$J$5:$J$130
Name 윤협최근주: OFFSET(#REF!,0,0,#REF!,1)
Name 일자: [1]전시일자별관람객!$C$3:$C$1549
Name 일차: OFFSET(b_line!$C$3,0,0,1,b_line!$B$2)
Name 일차수: OFFSET(b_line!$B$4,0,0,9,b_line!$D$1-1)
Name 잔여김정기: OFFSET(#REF!,#REF!,0,#REF!,1)
Name 잔여드리머: OFFSET(#REF!,#REF!,0,#REF!,1)
Name 잔여마르지엘라: OFFSET(#REF!,#REF!,0,#REF!,1)
Name 잔여바스키아: OFFSET(#REF!,#REF!,0,#REF!,1)
Name 잔여알렉스: OFFSET(#REF!,#REF!,0,#REF!,1)
Name 잔여오스틴리: OFFSET(#REF!,#REF!,0,#REF!,1)
Name 잔여제이알: OFFSET(#REF!,#REF!,0,#REF!,1)
Name 잔여페어리: OFFSET(#REF!,#REF!,0,#REF!,1)
Name 제이알: d_gra!$H$5:$H$130
Name 제이알최근주: OFFSET(#REF!,0,0,#REF!,1)
Name 페어리: d_gra!$F$5:$F$130
Name 페어리최근주: OFFSET(#REF!,0,0,#REF!,1)

Sheet 선형그래프
B2: 6
C15: =+b_stick!$O$5 -> 45

Sheet b_line
B2: 45
B3: 전시 | C3: 1 | D3: 2 | E3: 3 | F3: 4 | G3: 5 | H3: 6 | I3: 7 | J3: 8 | K3: 9 | L3: 10 | M3: 11 | N3: 12 | O3: 13 | P3: 14 | Q3: 15 | R3: 16 | S3: 17 | T3: 18 | U3: 19 | V3: 20 | W3: 21 | X3: 22 | Y3: 23 | Z3: 24 | AA3: 25 | AB3: 26 | AC3: 27 | AD3: 28 | AE3: 29 | AF3: 30 | AG3: 31 | AH3: 32 | AI3: 33 | AJ3: 34 | AK3: 35 | AL3: 36 | AM3: 37 | AN3: 38 | AO3: 39 | AP3: 40 | AQ3: 41 | AR3: 42 | AS3: 43 | AT3: 44 | AU3: 45 | AV3: 46 | AW3: 47 | AX3: 48 | AY3: 49 | AZ3: 50 | BA3: 51 | BB3: 52 | BC3: 53 | BD3: 54 | BE3: 55 | BF3: 56 | BG3: 57 | BH3: 58 | BI3: 59 | BJ3: 60 | BK3: 61 | BL3: 62 | BM3: 63 | BN3: 64 | BO3: 65 | BP3: 66 | BQ3: 67 | BR3: 68 | BS3: 69 | BT3: 70 | BU3: 71 | BV3: 72 | BW3: 73 | BX3: 74 | BY3: 75 | BZ3: 76 | CA3: 77 | CB3: 78 | CC3: 79 | CD3: 80 | CE3: 81 | CF3: 82 | CG3: 83 | CH3: 84 | CI3: 85 | CJ3: 86 | CK3: 87 | CL3: 88 | CM3: 89 | CN3: 90 | CO3: 91 | CP3: 92 | CQ3: 93 | CR3: 94 | CS3: 95 | CT3: 96 | CU3: 97 | CV3: 98 | CW3: 99 | CX3: 100 | CY3: 101 | CZ3: 102 | DA3: 103 | DB3: 104 | DC3: 105 | DD3: 106 | DE3: 107 | DF3: 108 | DG3: 109 | DH3: 110 | DI3: 111 | DJ3: 112 | DK3: 113 | DL3: 114 | DM3: 115 | DN3: 116 | DO3: 117 | DP3: 118 | DQ3: 119 | DR3: 120 | DS3: 121 | DT3: 122 | DU3: 123 | DV3: 124 | DW3: 125 | DX3: 126 | DY3: 127 | DZ3: 128 | EA3: 129 | EB3: 130 | EC3: 131 | ED3: 132 | EE3: 133 | EF3: 134 | EG3: 135 | EH3: 136
B4: 바스키아 | C4: 899 | D4: 1682 | E4: 1564 | F4: 1409 | G4: 614 | H4: 614 | I4: 727 | J4: 630 | K4: 659 | L4: 1752 | M4: 1355 | N4: 540 | O4: 547 | P4: 572 | Q4: 450 | R4: 676 | S4: 1741 | T4: 1210 | U4: 649 | V4: 491 | W4: 694 | X4: 558 | Y4: 765 | Z4: 1617 | AA4: 1241 | AB4: 480 | AC4: 566 | AD4: 616 | AE4: 549 | AF4: 740 | AG4: 1556 | AH4: 1267 | AI4: 719 | AJ4: 500 | AK4: 715 | AL4: 606 | AM4: 985 | AN4: 1776 | AO4: 1300 | AP4: 617 | AQ4: 579 | AR4: 697 | AS4: 561 | AT4: 755 | AU4: 1461 | AV4: 989 | AW4: 512 | AX4: 435 | AY4: 435 | AZ4: 374 | BA4: 410 | BB4: 764 | BC4: 650 | BD4: 346 | BE4: 240 | BF4: 221 | BG4: 301 | BH4: 383 | BI4: 534 | BJ4: 412 | BK4: 217 | BL4: 167 | BM4: 187 | BN4: 180 | BO4: 246 | BP4: 439 | BQ4: 248 | BR4: 151 | BS4: 173 | BT4: 129 | BU4: 156 | BV4: 211 | BW4: 278 | BX4: 291 | BY4: 195 | BZ4: 172 | CA4: 164 | CB4: 247 | CC4: 415 | CD4: 250 | CE4: 263 | CF4: 219 | CG4: 252 | CH4: 278 | CI4: 293 | CJ4: 0 | CK4: 563 | CL4: 427 | CM4: 158 | CN4: 176 | CO4: 178 | CP4: 169 | CQ4: 220 | CR4: 676 | CS4: 588 | CT4: 268 | CU4: 300 | CV4: 289 | CW4: 409 | CX4: 399 | CY4: 1151 | CZ4: 834 | DA4: 293 | DB4: 420 | DC4: 527 | DD4: 473 | DE4: 712 | DF4: 1369 | DG4: 1223 | DH4: 751 | DI4: 690 | DJ4: 960 | DK4: 637 | DL4: 965 | DM4: 1879 | DN4: 1832 | DO4: 1042 | DP4: 1091 | DQ4: 1156 | DR4: 1170 | DS4: 1393 | DT4: 2534 | DU4: 2391 | DV4: 642 | DW4: 694 | DX4: 783 | DY4: 0 | DZ4: 0 | EA4: 1939 | EB4: 1652 | EC4: 861 | ED4: 910 | EE4: 1057 | EF4: 1493 | EG4: 2014 | EH4: 3306
B5: 김정기 | C5: 158 | D5: 265 | E5: 151 | F5: 0 | G5: 70 | H5: 69 | I5: 132 | J5: 96 | K5: 254 | L5: 164 | M5: 106 | N5: 54 | O5: 90 | P5: 104 | Q5: 99 | R5: 281 | S5: 236 | T5: 105 | U5: 93 | V5: 217 | W5: 121 | X5: 76 | Y5: 283 | Z5: 229 | AA5: 80 | AB5: 56 | AC5: 55 | AD5: 61 | AE5: 86 | AF5: 283 | AG5: 281 | AH5: 60 | AI5: 83 | AJ5: 248 | AK5: 65 | AL5: 192 | AM5: 354 | AN5: 224 | AO5: 0 | AP5: 99 | AQ5: 105 | AR5: 51 | AS5: 76 | AT5: 251 | AU5: 158 | AV5: 51 | AW5: 32 | AX5: 36 | AY5: 57 | AZ5: 68 | BA5: 245 | BB5: 158 | BC5: 64 | BD5: 89 | BE5: 77 | BF5: 84 | BG5: 82 | BH5: 313 | BI5: 174 | BJ5: 0 | BK5: 69 | BL5: 62 | BM5: 115 | BN5: 130 | BO5: 337 | BP5: 214 | BQ5: 141 | BR5: 82 | BS5: 79 | BT5: 146 | BU5: 132 | BV5: 543 | BW5: 353 | BX5: 150 | BY5: 87 | BZ5: 241 | CA5: 238 | CB5: 251 | CC5: 656 | CD5: 473 | CE5: 220 | CF5: 256 | CG5: 216 | CH5: 338 | CI5: 354 | CJ5: 760 | CK5: 639 | CL5: 0 | CM5: 0 | CN5: 0 | CO5: 0 | CP5: 0 | CQ5: 0 | CR5: 0 | CS5: 0 | CT5: 0 | CU5: 0 | CV5: 0 | CW5: 0 | CX5: 0 | CY5: 0 | CZ5: 0 | DA5: 0 | DB5: 0 | DC5: 0 | DD5: 0 | DE5: 0 | DY5: 0 | DZ5: 0 | EA5: 0 | EB5: 0 | EC5: 0 | ED5: 0 | EE5: 0 | EF5: 0 | EG5: 0 | EH5: 0
B6: 드리머 | C6: 89 | D6: 98 | E6: 188 | F6: 158 | G6: 181 | H6: 36 | I6: 60 | J6: 73 | K6: 110 | L6: 344 | M6: 356 | N6: 225 | O6: 38 | P6: 72 | Q6: 44 | R6: 82 | S6: 331 | T6: 265 | U6: 0 | V6: 60 | W6: 65 | X6: 64 | Y6: 110 | Z6: 320 | AA6: 280 | AB6: 78 | AC6: 54 | AD6: 176 | AE6: 55 | AF6: 134 | AG6: 349 | AH6: 407 | AI6: 60 | AJ6: 61 | AK6: 96 | AL6: 85 | AM6: 155 | AN6: 372 | AO6: 355 | AP6: 0 | AQ6: 106 | AR6: 157 | AS6: 133 | AT6: 177 | AU6: 465 | AV6: 361 | AW6: 123 | AX6: 121 | AY6: 118 | AZ6: 127 | BA6: 244 | BB6: 569 | BC6: 527 | BD6: 124 | BE6: 202 | BF6: 252 | BG6: 122 | BH6: 243 | BI6: 561 | BJ6: 515 | BK6: 179 | BL6: 169 | BM6: 216 | BN6: 109 | BO6: 152 | BP6: 493 | BQ6: 388 | BR6: 108 | BS6: 92 | BT6: 70 | BU6: 100 | BV6: 134 | BW6: 316 | BX6: 302 | BY6: 96 | BZ6: 63 | CA6: 102 | CB6: 133 | CC6: 119 | CD6: 358 | CE6: 376 | CF6: 130 | CG6: 166 | CH6: 201 | CI6: 185 | CJ6: 257 | CK6: 578 | CL6: 432 | CM6: 305 | CN6: 332 | CO6: 633 | CP6: 503 | CQ6: 539 | CR6: 0 | CS6: 1215 | CT6: 121 | CU6: 239 | CV6: 390 | CW6: 400 | CX6: 493 | CY6: 1009 | CZ6: 1089 | DA6: 0 | DB6: 0 | DC6: 0 | DD6: 0 | DE6: 0 | DF6: 0 | DG6: 0 | DH6: 0 | DI6: 0 | DJ6: 0 | DK6: 0 | DL6: 0 | DM6: 0 | DN6: 0 | DO6: 0 | DP6: 0 | DQ6: 0 | DR6: 0 | DS6: 0 | DT6: 0 | DU6: 0 | DV6: 0 | DW6: 0 | DX6: 0 | DY6: 0 | DZ6: 0 | EA6: 0 | EB6: 0 | EC6: 0 | ED6: 0 | EE6: 0 | EF6: 0 | EG6: 0 | EH6: 0
B7: 알렉스 | C7: 285 | D7: 356 | E7: 130 | F7: 107 | G7: 143 | H7: 509 | I7: 390 | J7: 0 | K7: 129 | L7: 469 | M7: 135 | N7: 181 | O7: 569 | P7: 470 | Q7: 131 | R7: 137 | S7: 174 | T7: 119 | U7: 230 | V7: 661 | W7: 559 | X7: 202 | Y7: 184 | Z7: 128 | AA7: 160 | AB7: 203 | AC7: 841 | AD7: 701 | AE7: 250 | AF7: 240 | AG7: 419 | AH7: 457 | AI7: 210 | AJ7: 558 | AK7: 423 | AL7: 160 | AM7: 194 | AN7: 163 | AO7: 182 | AP7: 274 | AQ7: 656 | AR7: 406 | AS7: 173 | AT7: 170 | AU7: 138 | AV7: 157 | AW7: 189 | AX7: 466 | AY7: 324 | AZ7: 0 | BA7: 112 | BB7: 126 | BC7: 115 | BD7: 154 | BE7: 476 | BF7: 264 | BG7: 174 | BH7: 124 | BI7: 309 | BJ7: 228 | BK7: 289 | BL7: 564 | BM7: 327 | BN7: 131 | BO7: 149 | BP7: 80 | BQ7: 317 | BR7: 258 | BS7: 455 | BT7: 300 | BU7: 114 | BV7: 106 | BW7: 94 | BX7: 111 | BY7: 108 | BZ7: 604 | CA7: 456 | CB7: 127 | CC7: 130 | CD7: 123 | CE7: 128 | CF7: 219 | CG7: 665 | CH7: 528 | CI7: 0 | CJ7: 114 | CK7: 275 | CL7: 181 | CM7: 298 | CN7: 690 | CO7: 660 | CP7: 242 | CQ7: 285 | CR7: 718 | CS7: 240 | CT7: 403 | CU7: 858 | CV7: 784 | CW7: 1132 | CX7: 0 | CY7: 0 | CZ7: 0 | DA7: 0 | DB7: 0 | DC7: 0 | DD7: 0 | DE7: 0 | DF7: 0 | DG7: 0 | DH7: 0 | DI7: 0 | DJ7: 0 | DK7: 0 | DL7: 0 | DM7: 0 | DN7: 0 | DO7: 0 | DP7: 0 | DQ7: 0 | DR7: 0 | DS7: 0 | DT7: 0 | DU7: 0 | DV7: 0 | DW7: 0 | DX7: 0 | DY7: 0 | DZ7: 0 | EA7: 0 | EB7: 0 | EC7: 0 | ED7: 0 | EE7: 0 | EF7: 0 | EG7: 0 | EH7: 0
B8: 페어리 | C8: 342 | D8: 453 | E8: 338 | F8: 212 | G8: 211 | H8: 302 | I8: 232 | J8: 240 | K8: 489 | L8: 417 | M8: 230 | N8: 146 | O8: 226 | P8: 181 | Q8: 221 | R8: 453 | S8: 438 | T8: 474 | U8: 215 | V8: 155 | W8: 183 | X8: 226 | Y8: 507 | Z8: 395 | AA8: 30 | AB8: 210 | AC8: 194 | AD8: 212 | AE8: 296 | AF8: 602 | AG8: 577 | AH8: 254 | AI8: 212 | AJ8: 349 | AK8: 87 | AL8: 163 | AM8: 373 | AN8: 275 | AO8: 96 | AP8: 76 | AQ8: 138 | AR8: 127 | AS8: 0 | AT8: 0 | AU8: 295 | AV8: 327 | AW8: 77 | AX8: 79 | AY8: 198 | AZ8: 234 | BA8: 317 | BB8: 280 | BC8: 125 | BD8: 104 | BE8: 120 | BF8: 86 | BG8: 147 | BH8: 348 | BI8: 262 | BJ8: 99 | BK8: 87 | BL8: 169 | BM8: 73 | BN8: 136 | BO8: 400 | BP8: 439 | BQ8: 355 | BR8: 61 | BS8: 78 | BT8: 92 | BU8: 134 | BV8: 450 | BW8: 510 | BX8: 372 | BY8: 82 | BZ8: 124 | CA8: 70 | CB8: 192 | CC8: 524 | CD8: 445 | CE8: 0 | CF8: 194 | CG8: 91 | CH8: 110 | CI8: 124 | CJ8: 394 | CK8: 469 | CL8: 110 | CM8: 112 | CN8: 192 | CO8: 134 | CP8: 277 | CQ8: 457 | CR8: 402 | CS8: 168 | CT8: 164 | CU8: 241 | CV8: 212 | CW8: 278 | CX8: 799 | CY8: 816 | CZ8: 0 | DA8: 0 | DB8: 0 | DC8: 0 | DD8: 0 | DE8: 0 | DF8: 0 | DG8: 0 | DH8: 0 | DI8: 0 | DJ8: 0 | DK8: 0 | DL8: 0 | DM8: 0 | DN8: 0 | DO8: 0 | DP8: 0 | DQ8: 0 | DR8: 0 | DS8: 0 | DT8: 0 | DU8: 0 | DV8: 0 | DW8: 0 | DX8: 0 | DY8: 0 | DZ8: 0 | EA8: 0 | EB8: 0 | EC8: 0 | ED8: 0 | EE8: 0 | EF8: 0 | EG8: 0 | EH8: 0
B9: 마르지엘라 | C9: 1532 | D9: 1116 | E9: 632 | F9: 575 | G9: 573 | H9: 610 | I9: 747 | J9: 787 | K9: 0 | L9: 349 | M9: 367 | N9: 302 | O9: 339 | P9: 415 | Q9: 1098 | R9: 959 | S9: 395 | T9: 350 | U9: 424 | V9: 407 | W9: 462 | X9: 1337 | Y9: 928 | Z9: 420 | AA9: 382 | AB9: 365 | AC9: 319 | AD9: 510 | AE9: 0 | AF9: 0 | AG9: 809 | AH9: 694 | AI9: 424 | AJ9: 406 | AK9: 592 | AL9: 1310 | AM9: 1277 | AN9: 695 | AO9: 677 | AP9: 198 | AQ9: 186 | AR9: 256 | AS9: 638 | AT9: 507 | AU9: 258 | AV9: 245 | AW9: 195 | AX9: 190 | AY9: 294 | AZ9: 638 | BA9: 529 | BB9: 280 | BC9: 348 | BD9: 241 | BE9: 239 | BF9: 273 | BG9: 573 | BH9: 504 | BI9: 224 | BJ9: 196 | BK9: 471 | BL9: 228 | BM9: 234 | BN9: 554 | BO9: 465 | BP9: 259 | BQ9: 246 | BR9: 526 | BS9: 137 | BT9: 192 | BU9: 460 | BV9: 447 | BW9: 44 | BX9: 130 | BY9: 179 | BZ9: 152 | CA9: 213 | CB9: 575 | CC9: 417 | CD9: 164 | CE9: 197 | CF9: 168 | CG9: 185 | CH9: 232 | CI9: 739 | CJ9: 587 | CK9: 293 | CL9: 271 | CM9: 280 | CN9: 382 | CO9: 586 | CP9: 1007 | CQ9: 929 | CR9: 0 | CS9: 0 | CT9: 0 | CU9: 0 | CV9: 0 | CW9: 0 | CX9: 0 | CY9: 0 | CZ9: 0 | DA9: 0 | DB9: 0 | DC9: 0 | DD9: 0 | DE9: 0 | DF9: 0 | DG9: 0 | DH9: 0 | DI9: 0 | DJ9: 0 | DK9: 0 | DL9: 0 | DM9: 0 | DN9: 0 | DO9: 0 | DP9: 0 | DQ9: 0 | DR9: 0 | DS9: 0 | DT9: 0 | DU9: 0 | DV9: 0 | DW9: 0 | DX9: 0 | DY9: 0 | DZ9: 0 | EA9: 0 | EB9: 0 | EC9: 0 | ED9: 0 | EE9: 0 | EF9: 0 | EG9: 0 | EH9: 0
B10: 제이알 | C10: 106 | D10: 107 | E10: 287 | F10: 205 | G10: 115 | H10: 64 | I10: 106 | J10: 54 | K10: 96 | L10: 101 | M10: 282 | N10: 173 | O10: 85 | P10: 84 | Q10: 111 | R10: 107 | S10: 134 | T10: 213 | U10: 184 | V10: 59 | W10: 100 | X10: 73 | Y10: 97 | Z10: 112 | AA10: 266 | AB10: 204 | AC10: 200 | AD10: 68 | AE10: 128 | AF10: 54 | AG10: 122 | AH10: 157 | AI10: 164 | AJ10: 125 | AK10: 131 | AL10: 83 | AM10: 97 | AN10: 68 | AO10: 195 | AP10: 158 | AQ10: 25 | AR10: 122 | AS10: 102 | AT10: 74 | AU10: 159 | AV10: 194 | AW10: 154 | AX10: 84 | AY10: 62 | AZ10: 84 | BA10: 140 | BB10: 106 | BC10: 189 | BD10: 177 | BE10: 65 | BF10: 76 | BG10: 150 | BH10: 110 | BI10: 145 | BJ10: 223 | BK10: 318 | BL10: 140 | BM10: 81 | BN10: 137 | BO10: 120 | BP10: 166 | BQ10: 251 | BR10: 323 | BS10: 21 | BT10: 123 | BU10: 148 | BV10: 81 | BW10: 400 | BX10: 408 | BY10: 384 | BZ10: 147 | CA10: 87 | CB10: 122 | CC10: 126 | CD10: 194 | CE10: 497 | CF10: 437 | CG10: 197 | CH10: 175 | CI10: 288 | CJ10: 211 | CK10: 264 | CL10: 695 | CM10: 649 | CN10: 314 | CO10: 248 | CP10: 262 | CQ10: 364 | CR10: 361 | CS10: 701 | CT10: 786 | CU10: 0 | CV10: 0 | CW10: 0 | CX10: 0 | CY10: 0 | CZ10: 0 | DA10: 0 | DB10: 0 | DC10: 0 | DD10: 0 | DE10: 0 | DF10: 0 | DG10: 0 | DH10: 0 | DI10: 0 | DJ10: 0 | DK10: 0 | DL10: 0 | DM10: 0 | DN10: 0 | DO10: 0 | DP10: 0 | DQ10: 0 | DR10: 0 | DS10: 0 | DT10: 0 | DU10: 0 | DV10: 0 | DW10: 0 | DX10: 0 | DY10: 0 | DZ10: 0 | EA10: 0 | EB10: 0 | EC10: 0 | ED10: 0 | EE10: 0 | EF10: 0 | EG10: 0 | EH10: 0
B11: 오스틴 리 | C11: 227 | D11: 274 | E11: 124 | F11: 105 | G11: 413 | H11: 305 | I11: 349 | J11: 336 | K11: 120 | L11: 96 | M11: 202 | N11: 383 | O11: 404 | P11: 371 | Q11: 126 | R11: 99 | S11: 236 | T11: 189 | U11: 567 | V11: 341 | W11: 0 | X11: 114 | Y11: 129 | Z11: 159 | AA11: 203 | AB11: 525 | AC11: 353 | AD11: 163 | AE11: 105 | AF11: 130 | AG11: 120 | AH11: 177 | AI11: 326 | AJ11: 320 | AK11: 94 | AL11: 122 | AM11: 127 | AN11: 95 | AO11: 151 | AP11: 487 | AQ11: 427 | AR11: 0 | AS11: 135 | AT11: 161 | AU11: 126 | AV11: 153 | AW11: 521 | AX11: 523 | AY11: 157 | AZ11: 102 | BA11: 143 | BB11: 125 | BC11: 269 | BD11: 502 | BE11: 564 | BF11: 135 | BG11: 117 | BH11: 157 | BI11: 169 | BJ11: 263 | BK11: 544 | BL11: 532 | BM11: 136 | BN11: 138 | BO11: 146 | BP11: 118 | BQ11: 159 | BR11: 502 | BS11: 464 | BT11: 94 | BU11: 139 | BV11: 135 | BW11: 250 | BX11: 193 | BY11: 602 | BZ11: 482 | CA11: 161 | CB11: 188 | CC11: 236 | CD11: 154 | CE11: 451 | CF11: 619 | CG11: 542 | CH11: 263 | CI11: 234 | CJ11: 332 | CK11: 265 | CL11: 370 | CM11: 690 | CN11: 713 | CO11: 799 | CP11: 399 | CQ11: 421 | CR11: 564 | CS11: 689 | CT11: 772 | CU11: 1190 | CV11: 0 | CW11: 0 | CX11: 0 | CY11: 0 | CZ11: 0 | DA11: 0 | DB11: 0 | DC11: 0 | DD11: 0 | DE11: 0 | DF11: 0 | DG11: 0 | DH11: 0 | DI11: 0 | DJ11: 0 | DK11: 0 | DL11: 0 | DM11: 0 | DN11: 0 | DO11: 0 | DP11: 0 | DQ11: 0 | DR11: 0 | DS11: 0 | DT11: 0 | DU11: 0 | DV11: 0 | DW11: 0 | DX11: 0 | DY11: 0 | DZ11: 0 | EA11: 0 | EB11: 0 | EC11: 0 | ED11: 0 | EE11: 0 | EF11: 0 | EG11: 0 | EH11: 0
B12: 윤협 | C12: =+INDEX(b_stick!$L$9:$L$144,C$3) -> #REF! | D12: =+INDEX(b_stick!$L$9:$L$144,D$3) -> #REF! | E12: =+INDEX(b_stick!$L$9:$L$144,E$3) -> #REF! | F12: =+INDEX(b_stick!$L$9:$L$144,F$3) -> #REF! | G12: =+INDEX(b_stick!$L$9:$L$144,G$3) -> #REF! | H12: =+INDEX(b_stick!$L$9:$L$144,H$3) -> #REF! | I12: =+INDEX(b_stick!$L$9:$L$144,I$3) -> #REF! | J12: =+INDEX(b_stick!$L$9:$L$144,J$3) -> #REF! | ... EH12: =+INDEX(b_stick!$L$9:$L$144,EH$3) -> #REF!
F18: =SERIES(일차,,범위_바스키아,2)
F21: =+SUM(범위_바스키아) -> 40701
F22: =+SUM(일차) -> 1035

Sheet b_stick
X3: =+O5 -> 45
O5: =+b_line!B2 -> 45
N6: 바스키아 | O6: =+SUM(D8,OFFSET(D$8,0,0,$O$5+1)) -> #REF! | P6: =+O6/$O$5 -> #REF! | Q6: =+RANK(O6,$O$6:$O$14) -> #REF!
N7: 김정기 | O7: =+SUM(E8,OFFSET(E$8,0,0,$O$5+1)) -> #REF! | P7: =+O7/$O$5 -> #REF! | Q7: =+RANK(O7,$O$6:$O$14) -> #REF!
C8: 일차 | D8: 바스키아 | E8: 김정기 | F8: 드리머 | G8: 알렉스 | H8: 페어리 | I8: 마르지엘라 | J8: 제이알 | K8: 오스틴 리 | L8: 윤협 | N8: 드리머 | O8: =+SUM(F8,OFFSET(F$8,0,0,$O$5+1)) -> #REF! | P8: =+O8/$O$5 -> #REF! | Q8: =+RANK(O8,$O$6:$O$14) -> #REF!
C9: 1 | D9: =+#REF! -> #REF! | E9: =+#REF! -> #REF! | F9: =+#REF! -> #REF! | G9: =+#REF! -> #REF! | H9: =+#REF! -> #REF! | I9: =+#REF! -> #REF! | J9: =+#REF! -> #REF! | K9: =+#REF! -> #REF! | L9: =+#REF! -> #REF! | N9: 알렉스 | O9: =+SUM(G8,OFFSET(G$8,0,0,$O$5+1)) -> #REF! | P9: =+O9/$O$5 -> #REF! | Q9: =+RANK(O9,$O$6:$O$14) -> #REF!
C10: 2 | D10: =+#REF! -> #REF! | E10: =+#REF! -> #REF! | F10: =+#REF! -> #REF! | G10: =+#REF! -> #REF! | H10: =+#REF! -> #REF! | I10: =+#REF! -> #REF! | J10: =+#REF! -> #REF! | K10: =+#REF! -> #REF! | L10: =+#REF! -> #REF! | N10: 페어리 | O10: =+SUM(H8,OFFSET(H$8,0,0,$O$5+1)) -> #REF! | P10: =+O10/$O$5 -> #REF! | Q10: =+RANK(O10,$O$6:$O$14) -> #REF!
C11: 3 | D11: =+#REF! -> #REF! | E11: =+#REF! -> #REF! | F11: =+#REF! -> #REF! | G11: =+#REF! -> #REF! | H11: =+#REF! -> #REF! | I11: =+#REF! -> #REF! | J11: =+#REF! -> #REF! | K11: =+#REF! -> #REF! | L11: =+#REF! -> #REF! | N11: 마르지엘라 | O11: =+SUM(I8,OFFSET(I$8,0,0,$O$5+1)) -> #REF! | P11: =+O11/$O$5 -> #REF! | Q11: =+RANK(O11,$O$6:$O$14) -> #REF!
C12: 4 | D12: =+#REF! -> #REF! | E12: =+#REF! -> #REF! | F12: =+#REF! -> #REF! | G12: =+#REF! -> #REF! | H12: =+#REF! -> #REF! | I12: =+#REF! -> #REF! | J12: =+#REF! -> #REF! | K12: =+#REF! -> #REF! | L12: =+#REF! -> #REF! | N12: 제이알 | O12: =+SUM(J8,OFFSET(J$8,0,0,$O$5+1)) -> #REF! | P12: =+O12/$O$5 -> #REF! | Q12: =+RANK(O12,$O$6:$O$14) -> #REF!
C13: 5 | D13: =+#REF! -> #REF! | E13: =+#REF! -> #REF! | F13: =+#REF! -> #REF! | G13: =+#REF! -> #REF! | H13: =+#REF! -> #REF! | I13: =+#REF! -> #REF! | J13: =+#REF! -> #REF! | K13: =+#REF! -> #REF! | L13: =+#REF! -> #REF! | N13: 오스틴 리 | O13: =+SUM(K8,OFFSET(K$8,0,0,$O$5+1)) -> #REF! | P13: =+O13/$O$5 -> #REF! | Q13: =+RANK(O13,$O$6:$O$14) -> #REF!
C14: 6 | D14: =+#REF! -> #REF! | E14: =+#REF! -> #REF! | F14: =+#REF! -> #REF! | G14: =+#REF! -> #REF! | H14: =+#REF! -> #REF! | I14: =+#REF! -> #REF! | J14: =+#REF! -> #REF! | K14: =+#REF! -> #REF! | L14: =+#REF! -> #REF! | N14: 윤협 | O14: =+SUM(L8,OFFSET(L$8,0,0,$O$5+1)) -> #REF! | P14: =+O14/$O$5 -> #REF! | Q14: =+RANK(O14,$O$6:$O$14) -> #REF!
C15: 7 | D15: =+#REF! -> #REF! | E15: =+#REF! -> #REF! | F15: =+#REF! -> #REF! | G15: =+#REF! -> #REF! | H15: =+#REF! -> #REF! | I15: =+#REF! -> #REF! | J15: =+#REF! -> #REF! | K15: =+#REF! -> #REF! | L15: =+#REF! -> #REF!
C16: 8 | D16: =+#REF! -> #REF! | E16: =+#REF! -> #REF! | F16: =+#REF! -> #REF! | G16: =+#REF! -> #REF! | H16: =+#REF! -> #REF! | I16: =+#REF! -> #REF! | J16: =+#REF! -> #REF! | K16: =+#REF! -> #REF! | L16: =+#REF! -> #REF!
C17: 9 | D17: =+#REF! -> #REF! | E17: =+#REF! -> #REF! | F17: =+#REF! -> #REF! | G17: =+#REF! -> #REF! | H17: =+#REF! -> #REF! | I17: =+#REF! -> #REF! | J17: =+#REF! -> #REF! | K17: =+#REF! -> #REF! | L17: =+#REF! -> #REF!
C18: 10 | D18: =+#REF! -> #REF! | E18: =+#REF! -> #REF! | F18: =+#REF! -> #REF! | G18: =+#REF! -> #REF! | H18: =+#REF! -> #REF! | I18: =+#REF! -> #REF! | J18: =+#REF! -> #REF! | K18: =+#REF! -> #REF! | L18: =+#REF! -> #REF!
C19: 11 | D19: =+#REF! -> #REF! | E19: =+#REF! -> #REF! | F19: =+#REF! -> #REF! | G19: =+#REF! -> #REF! | H19: =+#REF! -> #REF! | I19: =+#REF! -> #REF! | J19: =+#REF! -> #REF! | K19: =+#REF! -> #REF! | L19: =+#REF! -> #REF!
C20: 12 | D20: =+#REF! -> #REF! | E20: =+#REF! -> #REF! | F20: =+#REF! -> #REF! | G20: =+#REF! -> #REF! | H20: =+#REF! -> #REF! | I20: =+#REF! -> #REF! | J20: =+#REF! -> #REF! | K20: =+#REF! -> #REF! | L20: =+#REF! -> #REF!
C21: 13 | D21: =+#REF! -> #REF! | E21: =+#REF! -> #REF! | F21: =+#REF! -> #REF! | G21: =+#REF! -> #REF! | H21: =+#REF! -> #REF! | I21: =+#REF! -> #REF! | J21: =+#REF! -> #REF! | K21: =+#REF! -> #REF! | L21: =+#REF! -> #REF!
C22: 14 | D22: =+#REF! -> #REF! | E22: =+#REF! -> #REF! | F22: =+#REF! -> #REF! | G22: =+#REF! -> #REF! | H22: =+#REF! -> #REF! | I22: =+#REF! -> #REF! | J22: =+#REF! -> #REF! | K22: =+#REF! -> #REF! | L22: =+#REF! -> #REF!
C23: 15 | D23: =+#REF! -> #REF! | E23: =+#REF! -> #REF! | F23: =+#REF! -> #REF! | G23: =+#REF! -> #REF! | H23: =+#REF! -> #REF! | I23: =+#REF! -> #REF! | J23: =+#REF! -> #REF! | K23: =+#REF! -> #REF! | L23: =+#REF! -> #REF!
C24: 16 | D24: =+#REF! -> #REF! | E24: =+#REF! -> #REF! | F24: =+#REF! -> #REF! | G24: =+#REF! -> #REF! | H24: =+#REF! -> #REF! | I24: =+#REF! -> #REF! | J24: =+#REF! -> #REF! | K24: =+#REF! -> #REF! | L24: =+#REF! -> #REF!
C25: 17 | D25: =+#REF! -> #REF! | E25: =+#REF! -> #REF! | F25: =+#REF! -> #REF! | G25: =+#REF! -> #REF! | H25: =+#REF! -> #REF! | I25: =+#REF! -> #REF! | J25: =+#REF! -> #REF! | K25: =+#REF! -> #REF! | L25: =+#REF! -> #REF!
C26: 18 | D26: =+#REF! -> #REF! | E26: =+#REF! -> #REF! | F26: =+#REF! -> #REF! | G26: =+#REF! -> #REF! | H26: =+#REF! -> #REF! | I26: =+#REF! -> #REF! | J26: =+#REF! -> #REF! | K26: =+#REF! -> #REF! | L26: =+#REF! -> #REF!
... C133: 125 | D133: =+#REF! -> #REF! | E133: =+#REF! -> #REF! | F133: =+#REF! -> #REF! | G133: =+#REF! -> #REF! | H133: =+#REF! -> #REF! | I133: =+#REF! -> #REF! | J133: =+#REF! -> #REF! | K133: =+#REF! -> #REF! | L133: =+#REF! -> #REF!
C134: =+C133+1 -> 126 | D134: =+#REF! -> #REF! | E134: =+#REF! -> #REF! | F134: =+#REF! -> #REF! | G134: =+#REF! -> #REF! | H134: =+#REF! -> #REF! | I134: =+#REF! -> #REF! | J134: =+#REF! -> #REF! | K134: =+#REF! -> #REF! | L134: =+#REF! -> #REF!
C135: =+C134+1 -> 127 | D135: =+#REF! -> #REF! | E135: =+#REF! -> #REF! | F135: =+#REF! -> #REF! | G135: =+#REF! -> #REF! | H135: =+#REF! -> #REF! | I135: =+#REF! -> #REF! | J135: =+#REF! -> #REF! | K135: =+#REF! -> #REF! | L135: =+#REF! -> #REF!
C136: =+C135+1 -> 128 | D136: =+#REF! -> #REF! | E136: =+#REF! -> #REF! | F136: =+#REF! -> #REF! | G136: =+#REF! -> #REF! | H136: =+#REF! -> #REF! | I136: =+#REF! -> #REF! | J136: =+#REF! -> #REF! | K136: =+#REF! -> #REF! | L136: =+#REF! -> #REF!
C137: =+C136+1 -> 129 | D137: =+#REF! -> #REF! | E137: =+#REF! -> #REF! | F137: =+#REF! -> #REF! | G137: =+#REF! -> #REF! | H137: =+#REF! -> #REF! | I137: =+#REF! -> #REF! | J137: =+#REF! -> #REF! | K137: =+#REF! -> #REF! | L137: =+#REF! -> #REF!
C138: =+C137+1 -> 130 | D138: =+#REF! -> #REF! | E138: =+#REF! -> #REF! | F138: =+#REF! -> #REF! | G138: =+#REF! -> #REF! | H138: =+#REF! -> #REF! | I138: =+#REF! -> #REF! | J138: =+#REF! -> #REF! | K138: =+#REF! -> #REF! | L138: =+#REF! -> #REF!
C139: =+C138+1 -> 131 | D139: =+#REF! -> #REF! | E139: =+#REF! -> #REF! | F139: =+#REF! -> #REF! | G139: =+#REF! -> #REF! | H139: =+#REF! -> #REF! | I139: =+#REF! -> #REF! | J139: =+#REF! -> #REF! | K139: =+#REF! -> #REF! | L139: =+#REF! -> #REF!
C140: =+C139+1 -> 132 | D140: =+#REF! -> #REF! | E140: =+#REF! -> #REF! | F140: =+#REF! -> #REF! | G140: =+#REF! -> #REF! | H140: =+#REF! -> #REF! | I140: =+#REF! -> #REF! | J140: =+#REF! -> #REF! | K140: =+#REF! -> #REF! | L140: =+#REF! -> #REF!
C141: =+C140+1 -> 133 | D141: =+#REF! -> #REF! | E141: =+#REF! -> #REF! | F141: =+#REF! -> #REF! | G141: =+#REF! -> #REF! | H141: =+#REF! -> #REF! | I141: =+#REF! -> #REF! | J141: =+#REF! -> #REF! | K141: =+#REF! -> #REF! | L141: =+#REF! -> #REF!
C142: =+C141+1 -> 134 | D142: =+#REF! -> #REF! | E142: =+#REF! -> #REF! | F142: =+#REF! -> #REF! | G142: =+#REF! -> #REF! | H142: =+#REF! -> #REF! | I142: =+#REF! -> #REF! | J142: =+#REF! -> #REF! | K142: =+#REF! -> #REF! | L142: =+#REF! -> #REF!
C143: =+C142+1 -> 135 | D143: =+#REF! -> #REF! | E143: =+#REF! -> #REF! | F143: =+#REF! -> #REF! | G143: =+#REF! -> #REF! | H143: =+#REF! -> #REF! | I143: =+#REF! -> #REF! | J143: =+#REF! -> #REF! | K143: =+#REF! -> #REF! | L143: =+#REF! -> #REF!
C144: =+C143+1 -> 136 | D144: =+#REF! -> #REF! | E144: =+#REF! -> #REF! | F144: =+#REF! -> #REF! | G144: =+#REF! -> #REF! | H144: =+#REF! -> #REF! | I144: =+#REF! -> #REF! | J144: =+#REF! -> #REF! | K144: =+#REF! -> #REF! | L144: =+#REF! -> #REF!

Sheet d_gra
A4: 일차 | B4: =+#REF! -> #REF! | C4: =+#REF! -> #REF! | D4: =+#REF! -> #REF! | E4: =+#REF! -> #REF! | F4: =+#REF! -> #REF! | G4: =+#REF! -> #REF! | H4: =+#REF! -> #REF! | I4: =+#REF! -> #REF! | J4: =+#REF! -> #REF!
A5: =+#REF! -> #REF! | B5: =+#REF! -> #REF! | C5: =+#REF! -> #REF! | D5: =+#REF! -> #REF! | E5: =+#REF! -> #REF! | F5: =+#REF! -> #REF! | G5: =+#REF! -> #REF! | H5: =+#REF! -> #REF! | ... J5: =+#REF! -> #REF!
A6: =+#REF! -> #REF! | B6: =+#REF! -> #REF! | C6: =+#REF! -> #REF! | D6: =+#REF! -> #REF! | E6: =+#REF! -> #REF! | F6: =+#REF! -> #REF! | G6: =+#REF! -> #REF! | H6: =+#REF! -> #REF! | ... J6: =+#REF! -> #REF!
A7: =+#REF! -> #REF! | B7: =+#REF! -> #REF! | C7: =+#REF! -> #REF! | D7: =+#REF! -> #REF! | E7: =+#REF! -> #REF! | F7: =+#REF! -> #REF! | G7: =+#REF! -> #REF! | H7: =+#REF! -> #REF! | ... J7: =+#REF! -> #REF!
A8: =+#REF! -> #REF! | B8: =+#REF! -> #REF! | C8: =+#REF! -> #REF! | D8: =+#REF! -> #REF! | E8: =+#REF! -> #REF! | F8: =+#REF! -> #REF! | G8: =+#REF! -> #REF! | H8: =+#REF! -> #REF! | ... J8: =+#REF! -> #REF!
A9: =+#REF! -> #REF! | B9: =+#REF! -> #REF! | C9: =+#REF! -> #REF! | D9: =+#REF! -> #REF! | E9: =+#REF! -> #REF! | F9: =+#REF! -> #REF! | G9: =+#REF! -> #REF! | H9: =+#REF! -> #REF! | ... J9: =+#REF! -> #REF!
A10: =+#REF! -> #REF! | B10: =+#REF! -> #REF! | C10: =+#REF! -> #REF! | D10: =+#REF! -> #REF! | E10: =+#REF! -> #REF! | F10: =+#REF! -> #REF! | G10: =+#REF! -> #REF! | H10: =+#REF! -> #REF! | ... J10: =+#REF! -> #REF!
A11: =+#REF! -> #REF! | B11: =+#REF! -> #REF! | C11: =+#REF! -> #REF! | D11: =+#REF! -> #REF! | E11: =+#REF! -> #REF! | F11: =+#REF! -> #REF! | G11: =+#REF! -> #REF! | H11: =+#REF! -> #REF! | ... J11: =+#REF! -> #REF!
A12: =+#REF! -> #REF! | B12: =+#REF! -> #REF! | C12: =+#REF! -> #REF! | D12: =+#REF! -> #REF! | E12: =+#REF! -> #REF! | F12: =+#REF! -> #REF! | G12: =+#REF! -> #REF! | H12: =+#REF! -> #REF! | ... J12: =+#REF! -> #REF!
A13: =+#REF! -> #REF! | B13: =+#REF! -> #REF! | C13: =+#REF! -> #REF! | D13: =+#REF! -> #REF! | E13: =+#REF! -> #REF! | F13: =+#REF! -> #REF! | G13: =+#REF! -> #REF! | H13: =+#REF! -> #REF! | ... J13: =+#REF! -> #REF!
A14: =+#REF! -> #REF! | B14: =+#REF! -> #REF! | C14: =+#REF! -> #REF! | D14: =+#REF! -> #REF! | E14: =+#REF! -> #REF! | F14: =+#REF! -> #REF! | G14: =+#REF! -> #REF! | H14: =+#REF! -> #REF! | ... J14: =+#REF! -> #REF!
A15: =+#REF! -> #REF! | B15: =+#REF! -> #REF! | C15: =+#REF! -> #REF! | D15: =+#REF! -> #REF! | E15: =+#REF! -> #REF! | F15: =+#REF! -> #REF! | G15: =+#REF! -> #REF! | H15: =+#REF! -> #REF! | ... J15: =+#REF! -> #REF!
A16: =+#REF! -> #REF! | B16: =+#REF! -> #REF! | C16: =+#REF! -> #REF! | D16: =+#REF! -> #REF! | E16: =+#REF! -> #REF! | F16: =+#REF! -> #REF! | G16: =+#REF! -> #REF! | H16: =+#REF! -> #REF! | ... J16: =+#REF! -> #REF!
... A130: =+#REF! -> #REF! | B130: =+#REF! -> #REF! | C130: =+#REF! -> #REF! | D130: =+#REF! -> #REF! | E130: =+#REF! -> #REF! | F130: =+#REF! -> #REF! | G130: =+#REF! -> #REF! | H130: =+#REF! -> #REF! | ... J130: =+#REF! -> #REF!

Sheet 일자별요약
A1: 뮤지엄 관람객 현황 | M1: 기준일자 | N1: =+daily!$N$2 -> 얼리버드비율 | P1: ★ 매주목 대표님 보고
A2: =+TEXT(N1,"yyyy-mm-dd")&TEXT(F7," (#,###일차)") -> #VALUE!
A3: ■ 관람객 실적 요약 | J3: (단위:명,일,%)
B4: 당일 관람객 | D4: =+INDEX(#REF!,$F$7) -> #REF! | E4: 목표 관람객 | F4: 40000 | G4: 일자 진도율 | H4: =+F7/$E$7 -> #VALUE! | I4: 관람객 진도율 | J4: =+I7/F4 -> #REF!
B6: 전시 | C6: 시작 | D6: 종료 | E6: 일수 | F6: 일차 | G6: 잔여일수 | H6: 일차 해당일자 | I6: 기간중 실적 | J6: 일평균 관람객
B7: 윤협 | C7: 45346 | D7: 45438 | E7: =+D7-C7+1 -> 93 | F7: =+$N$1-$C$7+1 -> #VALUE! | G7: =+E7-F7 -> #VALUE! | H7: =+TEXT(C7+F7-1,"yy.mm.dd") &TEXT(C7+F7-1," (aaa)") -> #VALUE! | I7: =+SUM(OFFSET(#REF!,0,0,일자별요약!$F$7,1)) -> #REF! | J7: =+I7/F7 -> #REF!
B8: 오스틴 리 | C8: 45195 | D8: 45291 | E8: =+D8-C8+1 -> 97 | F8: =+F7 -> #VALUE! | G8: =+E8-F8 -> #VALUE! | H8: =+TEXT(C8+F8-1,"yy.mm.dd") & " " &TEXT(C8+F8-1,"(aaa)") -> #VALUE! | I8: =+SUM(OFFSET(#REF!,0,0,일자별요약!$F$8,1)) -> #REF! | J8: =+I8/F8 -> #REF!
B9: 윤협 평일 | C9: =+#REF! -> #REF! | D9: =+#REF! -> #REF! | E9: 윤협 주말 | F9: =+#REF! -> #REF! | G9: =+#REF! -> #REF! | H9: =+#REF! -> #REF! | I9: =+I7-I8 -> #REF! | J9: =+J7-J8 -> #REF! | L9: =+SUM(C9,F9)=I7 -> #REF!
A11: ■ 추세감안 관람객 예상 (단순계산)
B12: 직전(오스틴 리) 평균관람객 차이 기준 | E12: 일평균 관람객기준 | H12: 예상편차
B13: =+ROUND($J$66+(J9*$E$8),-2) -> #REF! | E13: =+ROUND(J7*E7,-2) -> #REF! | H13: =+B13-E13 -> #REF!
B15: ■ 얼리버드 티켓 회수현황 (전일기준)
B16: 판매처 | C16: 판매단가 | D16: 판매 | E16: 취소/환불 | G16: 회수 | I16: 미사용 | J16: 관람객중 얼리버드비율
F17: % | H17: %(취소제외)
B18: 인터파크 | C18: 9000 | D18: 6141 | E18: 620 | F18: =+E18/D18*100 -> 10.096076 | G18: 1100 | H18: =+G18/(D18-E18)*100 -> 19.923927 | I18: =+D18-E18-G18 -> 4421 | J18: =+G22/I7 -> #REF!
B19: 29Cm | C19: 9000 | D19: 618 | E19: 42 | F19: =+E19/D19*100 -> 6.7961165 | G19: 177 | H19: =+G19/(D19-E19)*100 -> 30.729167 | I19: =+D19-E19-G19 -> 399
B20: 네이버 | C20: 9000 | D20: 2535 | E20: 213 | F20: =+E20/D20*100 -> 8.4023669 | G20: 594 | H20: =+G20/(D20-E20)*100 -> 25.581395 | I20: =+D20-E20-G20 -> 1728
B21: 카카오 | C21: 9000 | D21: 3293 | E21: 391 | F21: =+E21/D21*100 -> 11.873671 | G21: 385 | H21: =+G21/(D21-E21)*100 -> 13.266713 | I21: =+D21-E21-G21 -> 2517
B22: 계 | C22: 9000 | D22: =+SUM(D18:D21) -> 12587 | E22: =+SUM(E18:E21) -> 1266 | F22: =+E22/D22*100 -> 10.057996 | G22: =+SUM(G18:G21) -> 2256 | H22: =+G22/(D22-E22)*100 -> 19.927568 | I22: =+SUM(I18:I21) -> 9065
A24: ■ 최근 일주일 관람객 추이 (2020년 바스키아 이후 기준)
B25: 구분 | C25: =+F7 -> #VALUE! | D25: =+C25-1 -> #VALUE! | E25: =+D25-1 -> #VALUE! | F25: =+E25-1 -> #VALUE! | G25: =+F25-1 -> #VALUE! | H25: =+G25-1 -> #VALUE! | I25: =+H25-1 -> #VALUE!
B26: 윤협기준 일자 | C26: =+$N$1 -> 얼리버드비율 | D26: =+C26-1 -> #VALUE! | E26: =+D26-1 -> #VALUE! | F26: =+E26-1 -> #VALUE! | G26: =+F26-1 -> #VALUE! | H26: =+G26-1 -> #VALUE! | I26: =+H26-1 -> #VALUE! | J26: 트랜드
B27: 윤협기준 요일 | C27: =+TEXT(C26,"aaa") -> 얼리버드비율 | D27: =+TEXT(D26,"aaa") -> #VALUE! | E27: =+TEXT(E26,"aaa") -> #VALUE! | F27: =+TEXT(F26,"aaa") -> #VALUE! | G27: =+TEXT(G26,"aaa") -> #VALUE! | H27: =+TEXT(H26,"aaa") -> #VALUE! | I27: =+TEXT(I26,"aaa") -> #VALUE!
B28: 윤협 | C28: =+SUMPRODUCT((#REF!)*(#REF!=$B28)*(#REF!=C$25)) -> #REF! | D28: =+SUMPRODUCT((#REF!)*(#REF!=$B28)*(#REF!=D$25)) -> #REF! | E28: =+SUMPRODUCT((#REF!)*(#REF!=$B28)*(#REF!=E$25)) -> #REF! | F28: =+SUMPRODUCT((#REF!)*(#REF!=$B28)*(#REF!=F$25)) -> #REF! | G28: =+SUMPRODUCT((#REF!)*(#REF!=$B28)*(#REF!=G$25)) -> #REF! | H28: =+SUMPRODUCT((#REF!)*(#REF!=$B28)*(#REF!=H$25)) -> #REF! | I28: =+SUMPRODUCT((#REF!)*(#REF!=$B28)*(#REF!=I$25)) -> #REF!
B29: 오스틴 리 | C29: =+SUMPRODUCT((#REF!)*(#REF!=$B29)*(#REF!=C$25)) -> #REF! | D29: =+SUMPRODUCT((#REF!)*(#REF!=$B29)*(#REF!=D$25)) -> #REF! | E29: =+SUMPRODUCT((#REF!)*(#REF!=$B29)*(#REF!=E$25)) -> #REF! | F29: =+SUMPRODUCT((#REF!)*(#REF!=$B29)*(#REF!=F$25)) -> #REF! | G29: =+SUMPRODUCT((#REF!)*(#REF!=$B29)*(#REF!=G$25)) -> #REF! | H29: =+SUMPRODUCT((#REF!)*(#REF!=$B29)*(#REF!=H$25)) -> #REF! | I29: =+SUMPRODUCT((#REF!)*(#REF!=$B29)*(#REF!=I$25)) -> #REF!
B30: 제이알 | C30: =+SUMPRODUCT((#REF!)*(#REF!=$B30)*(#REF!=C$25)) -> #REF! | D30: =+SUMPRODUCT((#REF!)*(#REF!=$B30)*(#REF!=D$25)) -> #REF! | E30: =+SUMPRODUCT((#REF!)*(#REF!=$B30)*(#REF!=E$25)) -> #REF! | F30: =+SUMPRODUCT((#REF!)*(#REF!=$B30)*(#REF!=F$25)) -> #REF! | G30: =+SUMPRODUCT((#REF!)*(#REF!=$B30)*(#REF!=G$25)) -> #REF! | H30: =+SUMPRODUCT((#REF!)*(#REF!=$B30)*(#REF!=H$25)) -> #REF! | I30: =+SUMPRODUCT((#REF!)*(#REF!=$B30)*(#REF!=I$25)) -> #REF!
B31: 마르지엘라 | C31: =+SUMPRODUCT((#REF!)*(#REF!=$B31)*(#REF!=C$25)) -> #REF! | D31: =+SUMPRODUCT((#REF!)*(#REF!=$B31)*(#REF!=D$25)) -> #REF! | E31: =+SUMPRODUCT((#REF!)*(#REF!=$B31)*(#REF!=E$25)) -> #REF! | F31: =+SUMPRODUCT((#REF!)*(#REF!=$B31)*(#REF!=F$25)) -> #REF! | G31: =+SUMPRODUCT((#REF!)*(#REF!=$B31)*(#REF!=G$25)) -> #REF! | H31: =+SUMPRODUCT((#REF!)*(#REF!=$B31)*(#REF!=H$25)) -> #REF! | I31: =+SUMPRODUCT((#REF!)*(#REF!=$B31)*(#REF!=I$25)) -> #REF!
B32: 페어리 | C32: =+SUMPRODUCT((#REF!)*(#REF!=$B32)*(#REF!=C$25)) -> #REF! | D32: =+SUMPRODUCT((#REF!)*(#REF!=$B32)*(#REF!=D$25)) -> #REF! | E32: =+SUMPRODUCT((#REF!)*(#REF!=$B32)*(#REF!=E$25)) -> #REF! | F32: =+SUMPRODUCT((#REF!)*(#REF!=$B32)*(#REF!=F$25)) -> #REF! | G32: =+SUMPRODUCT((#REF!)*(#REF!=$B32)*(#REF!=G$25)) -> #REF! | H32: =+SUMPRODUCT((#REF!)*(#REF!=$B32)*(#REF!=H$25)) -> #REF! | I32: =+SUMPRODUCT((#REF!)*(#REF!=$B32)*(#REF!=I$25)) -> #REF!
B33: 알렉스 | C33: =+SUMPRODUCT((#REF!)*(#REF!=$B33)*(#REF!=C$25)) -> #REF! | D33: =+SUMPRODUCT((#REF!)*(#REF!=$B33)*(#REF!=D$25)) -> #REF! | E33: =+SUMPRODUCT((#REF!)*(#REF!=$B33)*(#REF!=E$25)) -> #REF! | F33: =+SUMPRODUCT((#REF!)*(#REF!=$B33)*(#REF!=F$25)) -> #REF! | G33: =+SUMPRODUCT((#REF!)*(#REF!=$B33)*(#REF!=G$25)) -> #REF! | H33: =+SUMPRODUCT((#REF!)*(#REF!=$B33)*(#REF!=H$25)) -> #REF! | I33: =+SUMPRODUCT((#REF!)*(#REF!=$B33)*(#REF!=I$25)) -> #REF!
B34: 드리머 | C34: =+SUMPRODUCT((#REF!)*(#REF!=$B34)*(#REF!=C$25)) -> #REF! | D34: =+SUMPRODUCT((#REF!)*(#REF!=$B34)*(#REF!=D$25)) -> #REF! | E34: =+SUMPRODUCT((#REF!)*(#REF!=$B34)*(#REF!=E$25)) -> #REF! | F34: =+SUMPRODUCT((#REF!)*(#REF!=$B34)*(#REF!=F$25)) -> #REF! | G34: =+SUMPRODUCT((#REF!)*(#REF!=$B34)*(#REF!=G$25)) -> #REF! | H34: =+SUMPRODUCT((#REF!)*(#REF!=$B34)*(#REF!=H$25)) -> #REF! | I34: =+SUMPRODUCT((#REF!)*(#REF!=$B34)*(#REF!=I$25)) -> #REF!
B35: 김정기 | C35: =+SUMPRODUCT((#REF!)*(#REF!=$B35)*(#REF!=C$25)) -> #REF! | D35: =+SUMPRODUCT((#REF!)*(#REF!=$B35)*(#REF!=D$25)) -> #REF! | E35: =+SUMPRODUCT((#REF!)*(#REF!=$B35)*(#REF!=E$25)) -> #REF! | F35: =+SUMPRODUCT((#REF!)*(#REF!=$B35)*(#REF!=F$25)) -> #REF! | G35: =+SUMPRODUCT((#REF!)*(#REF!=$B35)*(#REF!=G$25)) -> #REF! | H35: =+SUMPRODUCT((#REF!)*(#REF!=$B35)*(#REF!=H$25)) -> #REF! | I35: =+SUMPRODUCT((#REF!)*(#REF!=$B35)*(#REF!=I$25)) -> #REF!
B36: 바스키아 | C36: =+SUMPRODUCT((#REF!)*(#REF!=$B36)*(#REF!=C$25)) -> #REF! | D36: =+SUMPRODUCT((#REF!)*(#REF!=$B36)*(#REF!=D$25)) -> #REF! | E36: =+SUMPRODUCT((#REF!)*(#REF!=$B36)*(#REF!=E$25)) -> #REF! | F36: =+SUMPRODUCT((#REF!)*(#REF!=$B36)*(#REF!=F$25)) -> #REF! | G36: =+SUMPRODUCT((#REF!)*(#REF!=$B36)*(#REF!=G$25)) -> #REF! | H36: =+SUMPRODUCT((#REF!)*(#REF!=$B36)*(#REF!=H$25)) -> #REF! | I36: =+SUMPRODUCT((#REF!)*(#REF!=$B36)*(#REF!=I$25)) -> #REF!
B37: 전체평균 | C37: =+AVERAGE(C29:C36) -> #REF! | D37: =+AVERAGE(D29:D36) -> #REF! | E37: =+AVERAGE(E29:E36) -> #REF! | F37: =+AVERAGE(F29:F36) -> #REF! | G37: =+AVERAGE(G29:G36) -> #REF! | H37: =+AVERAGE(H29:H36) -> #REF! | I37: =+AVERAGE(I29:I36) -> #REF!
B38: 평균대비 윤협 | C38: =+C28-C37 -> #REF! | D38: =+D28-D37 -> #REF! | E38: =+E28-E37 -> #REF! | F38: =+F28-F37 -> #REF! | G38: =+G28-G37 -> #REF! | H38: =+H28-H37 -> #REF! | I38: =+I28-I37 -> #REF! | J38: =+AVERAGE(C38:I38) -> #REF!
B39: 국내작가평균 | C39: =+AVERAGE(C35,C34) -> #REF! | D39: =+AVERAGE(D35,D34) -> #REF! | E39: =+AVERAGE(E35,E34) -> #REF! | F39: =+AVERAGE(F35,F34) -> #REF! | G39: =+AVERAGE(G35,G34) -> #REF! | H39: =+AVERAGE(H35,H34) -> #REF! | I39: =+AVERAGE(I35,I34) -> #REF!
B40: 평균대비 윤협 | C40: =+C28-C39 -> #REF! | D40: =+D28-D39 -> #REF! | E40: =+E28-E39 -> #REF! | F40: =+F28-F39 -> #REF! | G40: =+G28-G39 -> #REF! | H40: =+H28-H39 -> #REF! | I40: =+I28-I39 -> #REF! | J40: =+AVERAGE(C40:I40) -> #REF!
B41: ※ Bold표시 : 전시별 해당주차 평균 이상 관람객
A43: =+F7 -> #VALUE! | J43: =+F8 -> #VALUE!
B44: =+#REF! -> #REF! | C44: =+#REF! -> #REF! | D44: =+#REF! -> #REF! | E44: =+#REF! -> #REF! | F44: =+#REF! -> #REF! | G44: =+#REF! -> #REF! | H44: =+#REF! -> #REF! | I44: =+#REF! -> #REF! | J44: =+#REF! -> #REF!
A45: 평일 | B45: =+#REF! -> #REF! | C45: =+#REF! -> #REF! | D45: =+#REF! -> #REF! | E45: =+#REF! -> #REF! | F45: =+#REF! -> #REF! | G45: =+#REF! -> #REF! | H45: =+#REF! -> #REF! | I45: =+#REF! -> #REF! | J45: =+#REF! -> #REF!
...

Sheet 별첨_전시별,주차별
B6: 해외전시 | I6: 국내전시 | L6: 윤협
B7: 바스키아 | C7: 알렉스 | D7: 페어리 | E7: 마르지엘라 | F7: 제이알 | G7: 오스틴 리 | H7: 평균 | I7: 김정기 | J7: 드리머 | K7: 평균 | M7: 국내평균 대비 | N7: 해외평균 대비
A8: 1 | B8: =+SUMPRODUCT((#REF!)*(#REF!=$A8)*(#REF!=B$7)) -> #REF! | C8: =+SUMPRODUCT((#REF!)*(#REF!=$A8)*(#REF!=C$7)) -> #REF! | D8: =+SUMPRODUCT((#REF!)*(#REF!=$A8)*(#REF!=D$7)) -> #REF! | E8: =+SUMPRODUCT((#REF!)*(#REF!=$A8)*(#REF!=E$7)) -> #REF! | F8: =+SUMPRODUCT((#REF!)*(#REF!=$A8)*(#REF!=F$7)) -> #REF! | G8: =+SUMPRODUCT((#REF!)*(#REF!=$A8)*(#REF!=G$7)) -> #REF! | H8: =+SUMPRODUCT((#REF!)*(#REF!=$A8)*(#REF!=H$7)) -> #REF! | I8: =+SUMPRODUCT((#REF!)*(#REF!=$A8)*(#REF!=I$7)) -> #REF! | ... L8: =+SUMPRODUCT((#REF!)*(#REF!=$A8)*(#REF!=L$7)) -> #REF!
A9: =+A8+1 -> 2 | B9: =+SUMPRODUCT((#REF!)*(#REF!=$A9)*(#REF!=B$7)) -> #REF! | C9: =+SUMPRODUCT((#REF!)*(#REF!=$A9)*(#REF!=C$7)) -> #REF! | D9: =+SUMPRODUCT((#REF!)*(#REF!=$A9)*(#REF!=D$7)) -> #REF! | E9: =+SUMPRODUCT((#REF!)*(#REF!=$A9)*(#REF!=E$7)) -> #REF! | F9: =+SUMPRODUCT((#REF!)*(#REF!=$A9)*(#REF!=F$7)) -> #REF! | G9: =+SUMPRODUCT((#REF!)*(#REF!=$A9)*(#REF!=G$7)) -> #REF! | H9: =+SUMPRODUCT((#REF!)*(#REF!=$A9)*(#REF!=H$7)) -> #REF! | I9: =+SUMPRODUCT((#REF!)*(#REF!=$A9)*(#REF!=I$7)) -> #REF! | ... L9: =+SUMPRODUCT((#REF!)*(#REF!=$A9)*(#REF!=L$7)) -> #REF!
A10: =+A9+1 -> 3 | B10: =+SUMPRODUCT((#REF!)*(#REF!=$A10)*(#REF!=B$7)) -> #REF! | C10: =+SUMPRODUCT((#REF!)*(#REF!=$A10)*(#REF!=C$7)) -> #REF! | D10: =+SUMPRODUCT((#REF!)*(#REF!=$A10)*(#REF!=D$7)) -> #REF! | E10: =+SUMPRODUCT((#REF!)*(#REF!=$A10)*(#REF!=E$7)) -> #REF! | F10: =+SUMPRODUCT((#REF!)*(#REF!=$A10)*(#REF!=F$7)) -> #REF! | G10: =+SUMPRODUCT((#REF!)*(#REF!=$A10)*(#REF!=G$7)) -> #REF! | H10: =+SUMPRODUCT((#REF!)*(#REF!=$A10)*(#REF!=H$7)) -> #REF! | I10: =+SUMPRODUCT((#REF!)*(#REF!=$A10)*(#REF!=I$7)) -> #REF! | ... L10: =+SUMPRODUCT((#REF!)*(#REF!=$A10)*(#REF!=L$7)) -> #REF!
A11: =+A10+1 -> 4 | B11: =+SUMPRODUCT((#REF!)*(#REF!=$A11)*(#REF!=B$7)) -> #REF! | C11: =+SUMPRODUCT((#REF!)*(#REF!=$A11)*(#REF!=C$7)) -> #REF! | D11: =+SUMPRODUCT((#REF!)*(#REF!=$A11)*(#REF!=D$7)) -> #REF! | E11: =+SUMPRODUCT((#REF!)*(#REF!=$A11)*(#REF!=E$7)) -> #REF! | F11: =+SUMPRODUCT((#REF!)*(#REF!=$A11)*(#REF!=F$7)) -> #REF! | G11: =+SUMPRODUCT((#REF!)*(#REF!=$A11)*(#REF!=G$7)) -> #REF! | H11: =+SUMPRODUCT((#REF!)*(#REF!=$A11)*(#REF!=H$7)) -> #REF! | I11: =+SUMPRODUCT((#REF!)*(#REF!=$A11)*(#REF!=I$7)) -> #REF! | ... L11: =+SUMPRODUCT((#REF!)*(#REF!=$A11)*(#REF!=L$7)) -> #REF!
A12: =+A11+1 -> 5 | B12: =+SUMPRODUCT((#REF!)*(#REF!=$A12)*(#REF!=B$7)) -> #REF! | C12: =+SUMPRODUCT((#REF!)*(#REF!=$A12)*(#REF!=C$7)) -> #REF! | D12: =+SUMPRODUCT((#REF!)*(#REF!=$A12)*(#REF!=D$7)) -> #REF! | E12: =+SUMPRODUCT((#REF!)*(#REF!=$A12)*(#REF!=E$7)) -> #REF! | F12: =+SUMPRODUCT((#REF!)*(#REF!=$A12)*(#REF!=F$7)) -> #REF! | G12: =+SUMPRODUCT((#REF!)*(#REF!=$A12)*(#REF!=G$7)) -> #REF! | H12: =+SUMPRODUCT((#REF!)*(#REF!=$A12)*(#REF!=H$7)) -> #REF! | I12: =+SUMPRODUCT((#REF!)*(#REF!=$A12)*(#REF!=I$7)) -> #REF! | ... L12: =+SUMPRODUCT((#REF!)*(#REF!=$A12)*(#REF!=L$7)) -> #REF!
A13: =+A12+1 -> 6 | B13: =+SUMPRODUCT((#REF!)*(#REF!=$A13)*(#REF!=B$7)) -> #REF! | C13: =+SUMPRODUCT((#REF!)*(#REF!=$A13)*(#REF!=C$7)) -> #REF! | D13: =+SUMPRODUCT((#REF!)*(#REF!=$A13)*(#REF!=D$7)) -> #REF! | E13: =+SUMPRODUCT((#REF!)*(#REF!=$A13)*(#REF!=E$7)) -> #REF! | F13: =+SUMPRODUCT((#REF!)*(#REF!=$A13)*(#REF!=F$7)) -> #REF! | G13: =+SUMPRODUCT((#REF!)*(#REF!=$A13)*(#REF!=G$7)) -> #REF! | H13: =+SUMPRODUCT((#REF!)*(#REF!=$A13)*(#REF!=H$7)) -> #REF! | I13: =+SUMPRODUCT((#REF!)*(#REF!=$A13)*(#REF!=I$7)) -> #REF! | ... L13: =+SUMPRODUCT((#REF!)*(#REF!=$A13)*(#REF!=L$7)) -> #REF!
A14: =+A13+1 -> 7 | B14: =+SUMPRODUCT((#REF!)*(#REF!=$A14)*(#REF!=B$7)) -> #REF! | C14: =+SUMPRODUCT((#REF!)*(#REF!=$A14)*(#REF!=C$7)) -> #REF! | D14: =+SUMPRODUCT((#REF!)*(#REF!=$A14)*(#REF!=D$7)) -> #REF! | E14: =+SUMPRODUCT((#REF!)*(#REF!=$A14)*(#REF!=E$7)) -> #REF! | F14: =+SUMPRODUCT((#REF!)*(#REF!=$A14)*(#REF!=F$7)) -> #REF! | G14: =+SUMPRODUCT((#REF!)*(#REF!=$A14)*(#REF!=G$7)) -> #REF! | H14: =+SUMPRODUCT((#REF!)*(#REF!=$A14)*(#REF!=H$7)) -> #REF! | I14: =+SUMPRODUCT((#REF!)*(#REF!=$A14)*(#REF!=I$7)) -> #REF! | ... L14: =+SUMPRODUCT((#REF!)*(#REF!=$A14)*(#REF!=L$7)) -> #REF!
A15: =+A14+1 -> 8 | B15: =+SUMPRODUCT((#REF!)*(#REF!=$A15)*(#REF!=B$7)) -> #REF! | C15: =+SUMPRODUCT((#REF!)*(#REF!=$A15)*(#REF!=C$7)) -> #REF! | D15: =+SUMPRODUCT((#REF!)*(#REF!=$A15)*(#REF!=D$7)) -> #REF! | E15: =+SUMPRODUCT((#REF!)*(#REF!=$A15)*(#REF!=E$7)) -> #REF! | F15: =+SUMPRODUCT((#REF!)*(#REF!=$A15)*(#REF!=F$7)) -> #REF! | G15: =+SUMPRODUCT((#REF!)*(#REF!=$A15)*(#REF!=G$7)) -> #REF! | H15: =+SUMPRODUCT((#REF!)*(#REF!=$A15)*(#REF!=H$7)) -> #REF! | I15: =+SUMPRODUCT((#REF!)*(#REF!=$A15)*(#REF!=I$7)) -> #REF! | ... L15: =+SUMPRODUCT((#REF!)*(#REF!=$A15)*(#REF!=L$7)) -> #REF!
A16: =+A15+1 -> 9 | B16: =+SUMPRODUCT((#REF!)*(#REF!=$A16)*(#REF!=B$7)) -> #REF! | C16: =+SUMPRODUCT((#REF!)*(#REF!=$A16)*(#REF!=C$7)) -> #REF! | D16: =+SUMPRODUCT((#REF!)*(#REF!=$A16)*(#REF!=D$7)) -> #REF! | E16: =+SUMPRODUCT((#REF!)*(#REF!=$A16)*(#REF!=E$7)) -> #REF! | F16: =+SUMPRODUCT((#REF!)*(#REF!=$A16)*(#REF!=F$7)) -> #REF! | G16: =+SUMPRODUCT((#REF!)*(#REF!=$A16)*(#REF!=G$7)) -> #REF! | H16: =+SUMPRODUCT((#REF!)*(#REF!=$A16)*(#REF!=H$7)) -> #REF! | I16: =+SUMPRODUCT((#REF!)*(#REF!=$A16)*(#REF!=I$7)) -> #REF! | ... L16: =+SUMPRODUCT((#REF!)*(#REF!=$A16)*(#REF!=L$7)) -> #REF!
A17: =+A16+1 -> 10 | B17: =+SUMPRODUCT((#REF!)*(#REF!=$A17)*(#REF!=B$7)) -> #REF! | C17: =+SUMPRODUCT((#REF!)*(#REF!=$A17)*(#REF!=C$7)) -> #REF! | D17: =+SUMPRODUCT((#REF!)*(#REF!=$A17)*(#REF!=D$7)) -> #REF! | E17: =+SUMPRODUCT((#REF!)*(#REF!=$A17)*(#REF!=E$7)) -> #REF! | F17: =+SUMPRODUCT((#REF!)*(#REF!=$A17)*(#REF!=F$7)) -> #REF! | G17: =+SUMPRODUCT((#REF!)*(#REF!=$A17)*(#REF!=G$7)) -> #REF! | H17: =+SUMPRODUCT((#REF!)*(#REF!=$A17)*(#REF!=H$7)) -> #REF! | I17: =+SUMPRODUCT((#REF!)*(#REF!=$A17)*(#REF!=I$7)) -> #REF! | ... L17: =+SUMPRODUCT((#REF!)*(#REF!=$A17)*(#REF!=L$7)) -> #REF!
A18: =+A17+1 -> 11 | B18: =+SUMPRODUCT((#REF!)*(#REF!=$A18)*(#REF!=B$7)) -> #REF! | C18: =+SUMPRODUCT((#REF!)*(#REF!=$A18)*(#REF!=C$7)) -> #REF! | D18: =+SUMPRODUCT((#REF!)*(#REF!=$A18)*(#REF!=D$7)) -> #REF! | E18: =+SUMPRODUCT((#REF!)*(#REF!=$A18)*(#REF!=E$7)) -> #REF! | F18: =+SUMPRODUCT((#REF!)*(#REF!=$A18)*(#REF!=F$7)) -> #REF! | G18: =+SUMPRODUCT((#REF!)*(#REF!=$A18)*(#REF!=G$7)) -> #REF! | H18: =+SUMPRODUCT((#REF!)*(#REF!=$A18)*(#REF!=H$7)) -> #REF! | I18: =+SUMPRODUCT((#REF!)*(#REF!=$A18)*(#REF!=I$7)) -> #REF! | ... L18: =+SUMPRODUCT((#REF!)*(#REF!=$A18)*(#REF!=L$7)) -> #REF!
A19: =+A18+1 -> 12 | B19: =+SUMPRODUCT((#REF!)*(#REF!=$A19)*(#REF!=B$7)) -> #REF! | C19: =+SUMPRODUCT((#REF!)*(#REF!=$A19)*(#REF!=C$7)) -> #REF! | D19: =+SUMPRODUCT((#REF!)*(#REF!=$A19)*(#REF!=D$7)) -> #REF! | E19: =+SUMPRODUCT((#REF!)*(#REF!=$A19)*(#REF!=E$7)) -> #REF! | F19: =+SUMPRODUCT((#REF!)*(#REF!=$A19)*(#REF!=F$7)) -> #REF! | G19: =+SUMPRODUCT((#REF!)*(#REF!=$A19)*(#REF!=G$7)) -> #REF! | H19: =+SUMPRODUCT((#REF!)*(#REF!=$A19)*(#REF!=H$7)) -> #REF! | I19: =+SUMPRODUCT((#REF!)*(#REF!=$A19)*(#REF!=I$7)) -> #REF! | ... L19: =+SUMPRODUCT((#REF!)*(#REF!=$A19)*(#REF!=L$7)) -> #REF!
A20: =+A19+1 -> 13 | B20: =+SUMPRODUCT((#REF!)*(#REF!=$A20)*(#REF!=B$7)) -> #REF! | C20: =+SUMPRODUCT((#REF!)*(#REF!=$A20)*(#REF!=C$7)) -> #REF! | D20: =+SUMPRODUCT((#REF!)*(#REF!=$A20)*(#REF!=D$7)) -> #REF! | E20: =+SUMPRODUCT((#REF!)*(#REF!=$A20)*(#REF!=E$7)) -> #REF! | F20: =+SUMPRODUCT((#REF!)*(#REF!=$A20)*(#REF!=F$7)) -> #REF! | G20: =+SUMPRODUCT((#REF!)*(#REF!=$A20)*(#REF!=G$7)) -> #REF! | H20: =+SUMPRODUCT((#REF!)*(#REF!=$A20)*(#REF!=H$7)) -> #REF! | I20: =+SUMPRODUCT((#REF!)*(#REF!=$A20)*(#REF!=I$7)) -> #REF! | ... L20: =+SUMPRODUCT((#REF!)*(#REF!=$A20)*(#REF!=L$7)) -> #REF!
... A27: =+A26+1 -> 20 | B27: =+SUMPRODUCT((#REF!)*(#REF!=$A27)*(#REF!=B$7)) -> #REF! | C27: =+SUMPRODUCT((#REF!)*(#REF!=$A27)*(#REF!=C$7)) -> #REF! | D27: =+SUMPRODUCT((#REF!)*(#REF!=$A27)*(#REF!=D$7)) -> #REF! | E27: =+SUMPRODUCT((#REF!)*(#REF!=$A27)*(#REF!=E$7)) -> #REF! | F27: =+SUMPRODUCT((#REF!)*(#REF!=$A27)*(#REF!=F$7)) -> #REF! | G27: =+SUMPRODUCT((#REF!)*(#REF!=$A27)*(#REF!=G$7)) -> #REF! | H27: =+SUMPRODUCT((#REF!)*(#REF!=$A27)*(#REF!=H$7)) -> #REF! | I27: =+SUMPRODUCT((#REF!)*(#REF!=$A27)*(#REF!=I$7)) -> #REF! | ... L27: =+SUMPRODUCT((#REF!)*(#REF!=$A27)*(#REF!=L$7)) -> #REF!

Sheet 주차별보고
A1: 뮤지엄 관람객 주차별 현황
A2: =+#REF! -> #REF!
A3: =+#REF! -> #REF!
A4: 1. 당일 차수 진도현황
A5: 구분 | D5: 경과 | G5: 잔여 | J5: 전체 | M5: 경과/진도율 | O5: 목표대비 평균관람객
D6: 일수 | E6: 누계 관람객 | F6: 평균 관람객 | G6: 일수 | H6: 누계 관람객 | I6: 평균 관람객 | J6: 일수 | K6: 누계 관람객 | L6: 평균 관람객 | M6: 기간 | N6: 관람객
A7: 윤협 | D7: =+#REF! -> #REF! | E7: =+#REF! -> #REF! | F7: =+E7/D7 -> #REF! | G7: =+J7-D7 -> #REF! | H7: =+K7-E7 -> #REF! | I7: =+H7/G7 -> #REF! | J7: =+#REF! -> #REF! | K7: 40000 | L7: =+K7/J7 -> #REF! | M7: =+D7/J7 -> #REF! | N7: =+E7/K7 -> #REF! | O7: =+F7-L7 -> #REF!
A8: 오스틴 리 | D8: =+D7 -> #REF! | E8: =+#REF! -> #REF! | F8: =+E8/D8 -> #REF! | G8: =+J8-D8 -> #REF! | H8: =+K8-E8 -> #REF! | I8: =+H8/G8 -> #REF! | J8: =+#REF! -> #REF! | K8: =+#REF! -> #REF! | L8: =+K8/J8 -> #REF! | M8: =+D8/J8 -> #REF! | N8: =+E8/K8 -> #REF! | O8: =+F8/L8 -> #REF!
A9: 직전전시 대비 | E9: =+E7-E8 -> #REF! | F9: =+F7-F8 -> #REF! | G9: =+G7-G8 -> #REF! | H9: =+H7-H8 -> #REF! | I9: =+I7-I8 -> #REF! | J9: =+J7-J8 -> #REF! | K9: =+K7-K8 -> #REF! | L9: =+L7-L8 -> #REF! | ... O9: =+O7-O8 -> #REF!
A10: 2. 전체기간 관람객 예상
D11: 직전(오스틴 리) 평균관람객 <낙관> | H11: 일평균 관람객 | L11: 마르지엘라 1주대비 지수 <비관>
A12: 전체기간 | D12: =+#REF! -> #REF! | H12: =+#REF! -> #REF! | L12: =+#REF! -> #REF!
A13: 일평균 관람객 | D13: =+#REF! -> #REF! | H13: =+#REF! -> #REF! | L13: =+#REF! -> #REF!
A14: 현추세 대비 | D14: =$F$7-+D13 -> #REF! | L14: =$F$7-+L13 -> #REF!
A16: 2. 전시별 2주 단위별 관람객 추이 _ 전시별 유형
C17: =+IF(C18<=#REF!,"완료","진행중") -> #REF! | D17: =+IF(D18<=#REF!,"완료","진행중") -> #REF! | E17: =+IF(E18<=#REF!,"완료","진행중") -> #REF! | F17: =+IF(F18<=#REF!,"완료","진행중") -> #REF! | G17: =+IF(G18<=#REF!,"완료","진행중") -> #REF! | H17: =+IF(H18<=#REF!,"완료","진행중") -> #REF! | I17: =+IF(I18<=#REF!,"완료","진행중") -> #REF! | J17: =+IF(J18<=#REF!,"완료","진행중") -> #REF! | ... L17: =+IF(L18<=#REF!,"완료","진행중") -> #REF! | O17: (단위 : 천명)
A18: 구분 | C18: 2 | D18: =+C18+2 -> 4 | E18: =+D18+2 -> 6 | F18: =+E18+2 -> 8 | G18: =+F18+2 -> 10 | H18: =+G18+2 -> 12 | I18: =+H18+2 -> 14 | J18: =+I18+2 -> 16 | K18: =+J18+2 -> 18 | L18: =+K18+2 -> 20 | M18: 누계 | N18: 트렌드 과거 -> 최근
A19: 해외 전시 | B19: 바스키아 | C19: =+SUMPRODUCT((#REF!)*(#REF!<=C$18)*(#REF!=$B19)) -> #REF! | D19: =+SUMPRODUCT((#REF!)*(#REF!<=D$18)*(#REF!=$B19))-SUM($C19:C19) -> #REF! | E19: =+SUMPRODUCT((#REF!)*(#REF!<=E$18)*(#REF!=$B19))-SUM($C19:D19) -> #REF! | F19: =+SUMPRODUCT((#REF!)*(#REF!<=F$18)*(#REF!=$B19))-SUM($C19:E19) -> #REF! | G19: =+SUMPRODUCT((#REF!)*(#REF!<=G$18)*(#REF!=$B19))-SUM($C19:F19) -> #REF! | H19: =+SUMPRODUCT((#REF!)*(#REF!<=H$18)*(#REF!=$B19))-SUM($C19:G19) -> #REF! | I19: =+SUMPRODUCT((#REF!)*(#REF!<=I$18)*(#REF!=$B19))-SUM($C19:H19) -> #REF! | J19: =+SUMPRODUCT((#REF!)*(#REF!<=J$18)*(#REF!=$B19))-SUM($C19:I19) -> #REF! | K19: =+SUMPRODUCT((#REF!)*(#REF!<=K$18)*(#REF!=$B19))-SUM($C19:J19) -> #REF! | L19: =+SUMPRODUCT((#REF!)*(#REF!<=L$18)*(#REF!=$B19))-SUM($C19:K19) -> #REF! | M19: =+SUM(C19:L19) -> #REF! | N19: 대기만성형 | P19: =+SUM(C19:L19) -> #REF!
B20: 알렉스 | C20: =+SUMPRODUCT((#REF!)*(#REF!<=C$18)*(#REF!=$B20)) -> #REF! | D20: =+SUMPRODUCT((#REF!)*(#REF!<=D$18)*(#REF!=$B20))-SUM($C20:C20) -> #REF! | E20: =+SUMPRODUCT((#REF!)*(#REF!<=E$18)*(#REF!=$B20))-SUM($C20:D20) -> #REF! | F20: =+SUMPRODUCT((#REF!)*(#REF!<=F$18)*(#REF!=$B20))-SUM($C20:E20) -> #REF! | G20: =+SUMPRODUCT((#REF!)*(#REF!<=G$18)*(#REF!=$B20))-SUM($C20:F20) -> #REF! | H20: =+SUMPRODUCT((#REF!)*(#REF!<=H$18)*(#REF!=$B20))-SUM($C20:G20) -> #REF! | I20: =+SUMPRODUCT((#REF!)*(#REF!<=I$18)*(#REF!=$B20))-SUM($C20:H20) -> #REF! | J20: =+SUMPRODUCT((#REF!)*(#REF!<=J$18)*(#REF!=$B20))-SUM($C20:I20) -> #REF! | K20: =+SUMPRODUCT((#REF!)*(#REF!<=K$18)*(#REF!=$B20))-SUM($C20:J20) -> #REF! | L20: =+SUMPRODUCT((#REF!)*(#REF!<=L$18)*(#REF!=$B20))-SUM($C20:K20) -> #REF! | M20: =+SUM(C20:L20) -> #REF! | N20: 일관형 | P20: =+SUM(C20:L20) -> #REF!
B21: 페어리 | C21: =+SUMPRODUCT((#REF!)*(#REF!<=C$18)*(#REF!=$B21)) -> #REF! | D21: =+SUMPRODUCT((#REF!)*(#REF!<=D$18)*(#REF!=$B21))-SUM($C21:C21) -> #REF! | E21: =+SUMPRODUCT((#REF!)*(#REF!<=E$18)*(#REF!=$B21))-SUM($C21:D21) -> #REF! | F21: =+SUMPRODUCT((#REF!)*(#REF!<=F$18)*(#REF!=$B21))-SUM($C21:E21) -> #REF! | G21: =+SUMPRODUCT((#REF!)*(#REF!<=G$18)*(#REF!=$B21))-SUM($C21:F21) -> #REF! | H21: =+SUMPRODUCT((#REF!)*(#REF!<=H$18)*(#REF!=$B21))-SUM($C21:G21) -> #REF! | I21: =+SUMPRODUCT((#REF!)*(#REF!<=I$18)*(#REF!=$B21))-SUM($C21:H21) -> #REF! | J21: =+SUMPRODUCT((#REF!)*(#REF!<=J$18)*(#REF!=$B21))-SUM($C21:I21) -> #REF! | K21: =+SUMPRODUCT((#REF!)*(#REF!<=K$18)*(#REF!=$B21))-SUM($C21:J21) -> #REF! | L21: =+SUMPRODUCT((#REF!)*(#REF!<=L$18)*(#REF!=$B21))-SUM($C21:K21) -> #REF! | M21: =+SUM(C21:L21) -> #REF! | N21: 용두사미형 | P21: =+SUM(C21:L21) -> #REF!
B22: 마르지엘라 | C22: =+SUMPRODUCT((#REF!)*(#REF!<=C$18)*(#REF!=$B22)) -> #REF! | D22: =+SUMPRODUCT((#REF!)*(#REF!<=D$18)*(#REF!=$B22))-SUM($C22:C22) -> #REF! | E22: =+SUMPRODUCT((#REF!)*(#REF!<=E$18)*(#REF!=$B22))-SUM($C22:D22) -> #REF! | F22: =+SUMPRODUCT((#REF!)*(#REF!<=F$18)*(#REF!=$B22))-SUM($C22:E22) -> #REF! | G22: =+SUMPRODUCT((#REF!)*(#REF!<=G$18)*(#REF!=$B22))-SUM($C22:F22) -> #REF! | H22: =+SUMPRODUCT((#REF!)*(#REF!<=H$18)*(#REF!=$B22))-SUM($C22:G22) -> #REF! | I22: =+SUMPRODUCT((#REF!)*(#REF!<=I$18)*(#REF!=$B22))-SUM($C22:H22) -> #REF! | J22: =+SUMPRODUCT((#REF!)*(#REF!<=J$18)*(#REF!=$B22))-SUM($C22:I22) -> #REF! | K22: =+SUMPRODUCT((#REF!)*(#REF!<=K$18)*(#REF!=$B22))-SUM($C22:J22) -> #REF! | L22: =+SUMPRODUCT((#REF!)*(#REF!<=L$18)*(#REF!=$B22))-SUM($C22:K22) -> #REF! | M22: =+SUM(C22:L22) -> #REF! | N22: 용두사미형 | P22: =+SUM(C22:L22) -> #REF!
B23: 제이알 | C23: =+SUMPRODUCT((#REF!)*(#REF!<=C$18)*(#REF!=$B23)) -> #REF! | D23: =+SUMPRODUCT((#REF!)*(#REF!<=D$18)*(#REF!=$B23))-SUM($C23:C23) -> #REF! | E23: =+SUMPRODUCT((#REF!)*(#REF!<=E$18)*(#REF!=$B23))-SUM($C23:D23) -> #REF! | F23: =+SUMPRODUCT((#REF!)*(#REF!<=F$18)*(#REF!=$B23))-SUM($C23:E23) -> #REF! | G23: =+SUMPRODUCT((#REF!)*(#REF!<=G$18)*(#REF!=$B23))-SUM($C23:F23) -> #REF! | H23: =+SUMPRODUCT((#REF!)*(#REF!<=H$18)*(#REF!=$B23))-SUM($C23:G23) -> #REF! | I23: =+SUMPRODUCT((#REF!)*(#REF!<=I$18)*(#REF!=$B23))-SUM($C23:H23) -> #REF! | J23: =+SUMPRODUCT((#REF!)*(#REF!<=J$18)*(#REF!=$B23))-SUM($C23:I23) -> #REF! | K23: =+SUMPRODUCT((#REF!)*(#REF!<=K$18)*(#REF!=$B23))-SUM($C23:J23) -> #REF! | L23: =+SUMPRODUCT((#REF!)*(#REF!<=L$18)*(#REF!=$B23))-SUM($C23:K23) -> #REF! | M23: =+SUM(C23:L23) -> #REF! | N23: 대기만성형 | P23: =+SUM(C23:L23) -> #REF!
B24: 오스틴 리 | C24: =+SUMPRODUCT((#REF!)*(#REF!<=C$18)*(#REF!=$B24)) -> #REF! | D24: =+SUMPRODUCT((#REF!)*(#REF!<=D$18)*(#REF!=$B24))-SUM($C24:C24) -> #REF! | E24: =+SUMPRODUCT((#REF!)*(#REF!<=E$18)*(#REF!=$B24))-SUM($C24:D24) -> #REF! | F24: =+SUMPRODUCT((#REF!)*(#REF!<=F$18)*(#REF!=$B24))-SUM($C24:E24) -> #REF! | G24: =+SUMPRODUCT((#REF!)*(#REF!<=G$18)*(#REF!=$B24))-SUM($C24:F24) -> #REF! | H24: =+SUMPRODUCT((#REF!)*(#REF!<=H$18)*(#REF!=$B24))-SUM($C24:G24) -> #REF! | I24: =+SUMPRODUCT((#REF!)*(#REF!<=I$18)*(#REF!=$B24))-SUM($C24:H24) -> #REF! | J24: =+SUMPRODUCT((#REF!)*(#REF!<=J$18)*(#REF!=$B24))-SUM($C24:I24) -> #REF! | K24: =+SUMPRODUCT((#REF!)*(#REF!<=K$18)*(#REF!=$B24))-SUM($C24:J24) -> #REF! | L24: =+SUMPRODUCT((#REF!)*(#REF!<=L$18)*(#REF!=$B24))-SUM($C24:K24) -> #REF! | M24: =+SUM(C24:L24) -> #REF! | N24: 대기만성형 | P24: =+SUM(C24:L24) -> #REF!
B25: 평균 | C25: =+AVERAGE(C19:C24) -> #REF! | D25: =+AVERAGE(D19:D24) -> #REF! | E25: =+AVERAGE(E19:E24) -> #REF! | F25: =+AVERAGE(F19:F24) -> #REF! | G25: =+AVERAGE(G19:G24) -> #REF! | H25: =+AVERAGE(H19:H24) -> #REF! | I25: =+AVERAGE(I19:I24) -> #REF! | J25: 0 | K25: 0 | L25: 0 | M25: =+SUM(C25:L25) -> #REF! | P25: =+SUM(C25:L25) -> #REF!
A26: 국내 전시 | B26: 김정기 | C26: =+SUMPRODUCT((#REF!)*(#REF!<=C$18)*(#REF!=$B26)) -> #REF! | D26: =+SUMPRODUCT((#REF!)*(#REF!<=D$18)*(#REF!=$B26))-SUM($C26:C26) -> #REF! | E26: =+SUMPRODUCT((#REF!)*(#REF!<=E$18)*(#REF!=$B26))-SUM($C26:D26) -> #REF! | F26: =+SUMPRODUCT((#REF!)*(#REF!<=F$18)*(#REF!=$B26))-SUM($C26:E26) -> #REF! | G26: =+SUMPRODUCT((#REF!)*(#REF!<=G$18)*(#REF!=$B26))-SUM($C26:F26) -> #REF! | H26: =+SUMPRODUCT((#REF!)*(#REF!<=H$18)*(#REF!=$B26))-SUM($C26:G26) -> #REF! | I26: =+SUMPRODUCT((#REF!)*(#REF!<=I$18)*(#REF!=$B26))-SUM($C26:H26) -> #REF! | J26: =+SUMPRODUCT((#REF!)*(#REF!<=J$18)*(#REF!=$B26))-SUM($C26:I26) -> #REF! | K26: =+SUMPRODUCT((#REF!)*(#REF!<=K$18)*(#REF!=$B26))-SUM($C26:J26) -> #REF! | L26: =+SUMPRODUCT((#REF!)*(#REF!<=L$18)*(#REF!=$B26))-SUM($C26:K26) -> #REF! | M26: =+SUM(C26:L26) -> #REF! | N26: 반짝형 | P26: =+SUM(C26:L26) -> #REF!
B27: 드리머 | C27: =+SUMPRODUCT((#REF!)*(#REF!<=C$18)*(#REF!=$B27)) -> #REF! | D27: =+SUMPRODUCT((#REF!)*(#REF!<=D$18)*(#REF!=$B27))-SUM($C27:C27) -> #REF! | E27: =+SUMPRODUCT((#REF!)*(#REF!<=E$18)*(#REF!=$B27))-SUM($C27:D27) -> #REF! | F27: =+SUMPRODUCT((#REF!)*(#REF!<=F$18)*(#REF!=$B27))-SUM($C27:E27) -> #REF! | G27: =+SUMPRODUCT((#REF!)*(#REF!<=G$18)*(#REF!=$B27))-SUM($C27:F27) -> #REF! | H27: =+SUMPRODUCT((#REF!)*(#REF!<=H$18)*(#REF!=$B27))-SUM($C27:G27) -> #REF! | I27: =+SUMPRODUCT((#REF!)*(#REF!<=I$18)*(#REF!=$B27))-SUM($C27:H27) -> #REF! | J27: =+SUMPRODUCT((#REF!)*(#REF!<=J$18)*(#REF!=$B27))-SUM($C27:I27) -> #REF! | K27: =+SUMPRODUCT((#REF!)*(#REF!<=K$18)*(#REF!=$B27))-SUM($C27:J27) -> #REF! | L27: =+SUMPRODUCT((#REF!)*(#REF!<=L$18)*(#REF!=$B27))-SUM($C27:K27) -> #REF! | M27: =+SUM(C27:L27) -> #REF! | N27: 반짝형 | P27: =+SUM(C27:L27) -> #REF!
B28: 평균 | C28: =+AVERAGE(C26:C27) -> #REF! | D28: =+AVERAGE(D26:D27) -> #REF! | E28: =+AVERAGE(E26:E27) -> #REF! | F28: =+AVERAGE(F26:F27) -> #REF! | G28: =+AVERAGE(G26:G27) -> #REF! | H28: =+AVERAGE(H26:H27) -> #REF! | I28: =+AVERAGE(I26:I27) -> #REF! | J28: =+AVERAGE(J26:J27) -> #REF! | ... L28: =+AVERAGE(L26:L27) -> #REF! | M28: =+SUM(C28:L28) -> #REF!
A29: 윤협 | C29: =+IF(C17="완료",SUMPRODUCT((#REF!)*(#REF!<=C$18)*(#REF!=$A29)),0) -> #REF! | D29: =+IF(D17="완료",SUMPRODUCT((#REF!)*(#REF!<=D$18)*(#REF!=$A29)),0) -> #REF! | E29: =+IF(E17="완료",SUMPRODUCT((#REF!)*(#REF!<=E$18)*(#REF!=$A29)),0) -> #REF! | F29: =+IF(F17="완료",SUMPRODUCT((#REF!)*(#REF!<=F$18)*(#REF!=$A29)),0) -> #REF! | G29: =+IF(G17="완료",SUMPRODUCT((#REF!)*(#REF!<=G$18)*(#REF!=$A29)),0) -> #REF! | H29: =+IF(H17="완료",SUMPRODUCT((#REF!)*(#REF!<=H$18)*(#REF!=$A29)),0) -> #REF! | I29: =+IF(I17="완료",SUMPRODUCT((#REF!)*(#REF!<=I$18)*(#REF!=$A29)),0) -> #REF! | J29: =+IF(J17="완료",SUMPRODUCT((#REF!)*(#REF!<=J$18)*(#REF!=$A29)),0) -> #REF! | ... L29: =+IF(L17="완료",SUMPRODUCT((#REF!)*(#REF!<=L$18)*(#REF!=$A29)),0) -> #REF! | M29: =+SUM(C29:L29) -> #REF!
B30: 국내평균 대비 | C30: =+IF(C29=0,0,C29-C28) -> #REF! | D30: =+IF(D29=0,0,D29-D28) -> #REF! | E30: =+IF(E29=0,0,E29-E28) -> #REF! | F30: =+IF(F29=0,0,F29-F28) -> #REF! | G30: =+IF(G29=0,0,G29-G28) -> #REF! | H30: =+IF(H29=0,0,H29-H28) -> #REF! | I30: =+IF(I29=0,0,I29-I28) -> #REF! | J30: =+IF(J29=0,0,J29-J28) -> #REF! | ... L30: =+IF(L29=0,0,L29-L28) -> #REF! | M30: =+SUM(C30:L30) -> #REF!
B31: 해외평균 대비 | C31: =+IF(C29=0,0,C29-C25) -> #REF! | D31: =+IF(D29=0,0,D29-D25) -> #REF! | E31: =+IF(E29=0,0,E29-E25) -> #REF! | F31: =+IF(F29=0,0,F29-F25) -> #REF! | G31: =+IF(G29=0,0,G29-G25) -> #REF! | H31: =+IF(H29=0,0,H29-H25) -> #REF! | I31: =+IF(I29=0,0,I29-I25) -> #REF! | J31: =+IF(J29=0,0,J29-J25) -> #REF! | ... L31: =+IF(L29=0,0,L29-L25) -> #REF! | M31: =+SUM(C31:L31) -> #REF!
A33: 3. 증감지수 산출 | M33: 초중기 | N33: 후기 | O33: (단위 : 천명)
A34: 구분 | C34: 2 | D34: =+C34+2 -> 4 | E34: =+D34+2 -> 6 | F34: =+E34+2 -> 8 | G34: =+F34+2 -> 10 | H34: =+G34+2 -> 12 | I34: =+H34+2 -> 14 | J34: =+I34+2 -> 16 | K34: =+J34+2 -> 18 | L34: =+K34+2 -> 20 | M34: 8w | N34: 9w~ | O34: 초중기 대비
A35: 용두사미형 | C35: =+SUMIFS(C$19:C$28,$N$19:$N$28,$A35) -> #REF! | D35: =+SUMIFS(D$19:D$28,$N$19:$N$28,$A35) -> #REF! | E35: =+SUMIFS(E$19:E$28,$N$19:$N$28,$A35) -> #REF! | F35: =+SUMIFS(F$19:F$28,$N$19:$N$28,$A35) -> #REF! | G35: =+SUMIFS(G$19:G$28,$N$19:$N$28,$A35) -> #REF! | H35: =+SUMIFS(H$19:H$28,$N$19:$N$28,$A35) -> #REF! | I35: =+SUMIFS(I$19:I$28,$N$19:$N$28,$A35) -> #REF! | J35: =+SUMIFS(J$19:J$28,$N$19:$N$28,$A35) -> #REF! | ... L35: =+SUMIFS(L$19:L$28,$N$19:$N$28,$A35) -> #REF! | M35: =+SUM(C35:F35) -> #REF! | N35: =+SUM(G35:L35) -> #REF! | O35: =+N35-M35 -> #REF!
B36: 첫2주대비 지수 | C36: =+C35/$C35 -> #REF! | D36: =+D35/$C35 -> #REF! | E36: =+E35/$C35 -> #REF! | F36: =+F35/$C35 -> #REF! | G36: =+G35/$C35 -> #REF! | H36: =+H35/$C35 -> #REF! | I36: =+AVERAGE(I35:J35)/$C35 -> #REF! | J36: =+J35/$C35 -> #REF! | O36: =+O35/M35 -> #REF!
A37: 대기만성형 | C37: =+SUMIFS(C$19:C$28,$N$19:$N$28,$A37) -> #REF! | D37: =+SUMIFS(D$19:D$28,$N$19:$N$28,$A37) -> #REF! | E37: =+SUMIFS(E$19:E$28,$N$19:$N$28,$A37) -> #REF! | F37: =+SUMIFS(F$19:F$28,$N$19:$N$28,$A37) -> #REF! | G37: =+SUMIFS(G$19:G$28,$N$19:$N$28,$A37) -> #REF! | H37: =+SUMIFS(H$19:H$28,$N$19:$N$28,$A37) -> #REF! | I37: =+SUMIFS(I$19:I$28,$N$19:$N$28,$A37) -> #REF! | J37: =+SUMIFS(J$19:J$28,$N$19:$N$28,$A37) -> #REF! | ... L37: =+SUMIFS(L$19:L$28,$N$19:$N$28,$A37) -> #REF! | M37: =+SUM(C37:F37) -> #REF! | N37: =+SUM(G37:L37) -> #REF! | O37: =+N37-M37 -> #REF!
B38: 첫2주대비 지수 | C38: =+C37/$C37 -> #REF! | D38: =+D37/$C37 -> #REF! | E38: =+E37/$C37 -> #REF! | F38: =+F37/$C37 -> #REF! | G38: =+G37/$C37 -> #REF! | H38: =+H37/$C37 -> #REF! | I38: =+SUM(I37:L37)/$C37 -> #REF! | J38: =+J37/$C19 -> #REF! | K38: =+K37/$C19 -> #REF! | L38: =+L37/$C19 -> #REF! | O38: =+O37/M37 -> #REF!
A39: 일관형 | C39: =+SUMIFS(C$19:C$28,$N$19:$N$28,$A39) -> #REF! | D39: =+SUMIFS(D$19:D$28,$N$19:$N$28,$A39) -> #REF! | E39: =+SUMIFS(E$19:E$28,$N$19:$N$28,$A39) -> #REF! | F39: =+SUMIFS(F$19:F$28,$N$19:$N$28,$A39) -> #REF! | G39: =+SUMIFS(G$19:G$28,$N$19:$N$28,$A39) -> #REF! | H39: =+SUMIFS(H$19:H$28,$N$19:$N$28,$A39) -> #REF! | I39: =+SUMIFS(I$19:I$28,$N$19:$N$28,$A39) -> #REF! | M39: =+SUM(C39:F39) -> #REF! | N39: =+SUM(G39:L39) -> #REF! | O39: =+N39-M39 -> #REF!
B40: 첫2주대비 지수 | C40: =+C39/$C39 -> #REF! | D40: =+D39/$C39 -> #REF! | E40: =+E39/$C39 -> #REF! | F40: =+F39/$C39 -> #REF! | G40: =+G39/$C39 -> #REF! | H40: =+H39/$C39 -> #REF! | I40: =+I39/$C39 -> #REF! | O40: =+O39/M39 -> #REF!
A41: 국내전시평균(반짝형) | C41: =+C28 -> #REF! | D41: =+D28 -> #REF! | E41: =+E28 -> #REF! | F41: =+F28 -> #REF! | G41: =+G28 -> #REF! | H41: =+H28 -> #REF! | I41: =+I28 -> #REF! | J41: =+J28 -> #REF! | M41: =+SUM(C41:F41) -> #REF! | N41: =+SUM(G41:L41) -> #REF! | O41: =+N41-M41 -> #REF!
B42: 첫2주대비 지수 | C42: =+C41/$C$41 -> #REF! | D42: =+D41/$C$41 -> #REF! | E42: =+E41/$C$41 -> #REF! | F42: =+F41/$C$41 -> #REF! | G42: =+G41/$C$41 -> #REF! | H42: =+H41/$C$41 -> #REF! | I42: =+I41/$C$41 -> #REF! | J42: =+J41/$C$41 -> #REF! | O42: =+O41/M41 -> #REF!
...

Sheet Sheet1
A1: https://wikidocs.net/157782

Sheet daily
A2: 년 | B2: 월 | C2: 요일 | D2: 일자 | E2: 관람객 | F2: 전시명 | G2: 무료 | H2: 유료 | I2: 일차 | J2: 평일휴일 | K2: 얼리버드 | L2: 슈퍼얼리버드 | M2: 얼리버드계 | N2: 얼리버드비율
A3: 2020 | B3: 10 | C3: 목 | D3: 44112 | E3: 899 | F3: 바스키아 | G3: 13 | H3: 886 | I3: 1 | J3: =+IF(OR(C3="토",C3="일"),"주말","평일") -> 평일
A4: 2020 | B4: 10 | C4: 금 | D4: 44113 | E4: 1682 | F4: 바스키아 | G4: 30 | H4: 1652 | I4: 2 | J4: =+IF(OR(C4="토",C4="일"),"주말","평일") -> 평일
A5: 2020 | B5: 10 | C5: 토 | D5: 44114 | E5: 1564 | F5: 바스키아 | G5: 25 | H5: 1539 | I5: 3 | J5: =+IF(OR(C5="토",C5="일"),"주말","평일") -> 주말
A6: 2020 | B6: 10 | C6: 일 | D6: 44115 | E6: 1409 | F6: 바스키아 | G6: 19 | H6: 1390 | I6: 4 | J6: =+IF(OR(C6="토",C6="일"),"주말","평일") -> 주말
A7: 2020 | B7: 10 | C7: 월 | D7: 44116 | E7: 614 | F7: 바스키아 | G7: 0 | H7: 614 | I7: 5 | J7: =+IF(OR(C7="토",C7="일"),"주말","평일") -> 평일
A8: 2020 | B8: 10 | C8: 화 | D8: 44117 | E8: 614 | F8: 바스키아 | G8: 16 | H8: 598 | I8: 6 | J8: =+IF(OR(C8="토",C8="일"),"주말","평일") -> 평일
A9: 2020 | B9: 10 | C9: 수 | D9: 44118 | E9: 727 | F9: 바스키아 | G9: 15 | H9: 712 | I9: 7 | J9: =+IF(OR(C9="토",C9="일"),"주말","평일") -> 평일
A10: 2020 | B10: 10 | C10: 목 | D10: 44119 | E10: 630 | F10: 바스키아 | G10: 30 | H10: 600 | I10: 8 | J10: =+IF(OR(C10="토",C10="일"),"주말","평일") -> 평일
A11: 2020 | B11: 10 | C11: 금 | D11: 44120 | E11: 659 | F11: 바스키아 | G11: 22 | H11: 637 | I11: 9 | J11: =+IF(OR(C11="토",C11="일"),"주말","평일") -> 평일
A12: 2020 | B12: 10 | C12: 토 | D12: 44121 | E12: 1752 | F12: 바스키아 | G12: 40 | H12: 1712 | I12: 10 | J12: =+IF(OR(C12="토",C12="일"),"주말","평일") -> 주말
A13: 2020 | B13: 10 | C13: 일 | D13: 44122 | E13: 1355 | F13: 바스키아 | G13: 22 | H13: 1333 | I13: 11 | J13: =+IF(OR(C13="토",C13="일"),"주말","평일") -> 주말
A14: 2020 | B14: 10 | C14: 월 | D14: 44123 | E14: 540 | F14: 바스키아 | G14: 15 | H14: 525 | I14: 12 | J14: =+IF(OR(C14="토",C14="일"),"주말","평일") -> 평일
